Workbook

Sheet EXP
A1: TOTAL_BASIC | B1: Statistiques de base au total
A2: PER_GAME_BASIC | B2: Statistiques de base par match
A3: ADVANCED | B3: Statistiques avancées

Sheet TOTAL_BASIC
A1: DATA
A2: Rank | B2: Player | C2: G | D2: MP | E2: PTS | F2: FG | G2: FGA | H2: 3P | I2: 3PA | J2: FT | K2: FTA | L2: ORB | M2: DRB | N2: TRB | O2: AST | P2: STL | Q2: BLK | R2: TOV | S2: PF | T2: 2P | U2: 2PA
A3: 1 | B3: Chelsea Gray | C3: 10 | D3: 225 | E3: 259 | F3: 91 | G3: 178 | H3: 34 | I3: 73 | J3: 21 | K3: 22 | L3: 7 | M3: 50 | N3: 57 | O3: 68 | P3: 16 | Q3: 5 | R3: 23 | S3: 23 | T3: =F3-H3 -> 57 | U3: =G3-I3 -> 105
A4: 2 | B4: Paige Bueckers | C4: 10 | D4: 206 | E4: 250 | F4: 96 | G4: 173 | H4: 15 | I4: 38 | J4: 27 | K4: 30 | L4: 5 | M4: 58 | N4: 63 | O4: 67 | P4: 9 | Q4: 6 | R4: 24 | S4: 29 | T4: =F4-H4 -> 81 | U4: =G4-I4 -> 135
A5: 3 | B5: Marina Mabrey | C5: 9 | D5: 189 | E5: 241 | F5: 88 | G5: 203 | H5: 34 | I5: 104 | J5: 19 | K5: 22 | L5: 7 | M5: 59 | N5: 66 | O5: 43 | P5: 4 | Q5: 2 | R5: 31 | S5: 28 | T5: =F5-H5 -> 54 | U5: =G5-I5 -> 99
A6: 4 | B6: Kelsey Plum | C6: 10 | D6: 186 | E6: 216 | F6: 82 | G6: 167 | H6: 27 | I6: 71 | J6: 16 | K6: 16 | L6: 9 | M6: 46 | N6: 55 | O6: 56 | P6: 3 | Q6: 1 | R6: 15 | S6: 32 | T6: =F6-H6 -> 55 | U6: =G6-I6 -> 96
A7: 5 | B7: Breanna Stewart | C7: 10 | D7: 168 | E7: 201 | F7: 76 | G7: 157 | H7: 9 | I7: 37 | J7: 23 | K7: 27 | L7: 15 | M7: 77 | N7: 92 | O7: 26 | P7: 11 | Q7: 6 | R7: 18 | S7: 19 | T7: =F7-H7 -> 67 | U7: =G7-I7 -> 120
A8: 6 | B8: Allisha Gray | C8: 10 | D8: 158 | E8: 201 | F8: 68 | G8: 158 | H8: 22 | I8: 67 | J8: 22 | K8: 26 | L8: 9 | M8: 34 | N8: 43 | O8: 30 | P8: 9 | Q8: 8 | R8: 16 | S8: 18 | T8: =F8-H8 -> 46 | U8: =G8-I8 -> 91
A9: 7 | B9: Dearica Hamby | C9: 10 | D9: 158 | E9: 192 | F9: 78 | G9: 138 | H9: 3 | I9: 14 | J9: 18 | K9: 30 | L9: 18 | M9: 65 | N9: 83 | O9: 8 | P9: 7 | Q9: 0 | R9: 10 | S9: 33 | T9: =F9-H9 -> 75 | U9: =G9-I9 -> 124
A10: 8 | B10: Brittney Sykes | C10: 10 | D10: 154 | E10: 189 | F10: 69 | G10: 145 | H10: 22 | I10: 52 | J10: 16 | K10: 21 | L10: 4 | M10: 34 | N10: 38 | O10: 17 | P10: 16 | Q10: 3 | R10: 20 | S10: 32 | T10: =F10-H10 -> 47 | U10: =G10-I10 -> 93
A11: 9 | B11: Aliyah Boston | C11: 10 | D11: 177 | E11: 186 | F11: 78 | G11: 149 | H11: 10 | I11: 32 | J11: 11 | K11: 15 | L11: 19 | M11: 76 | N11: 95 | O11: 26 | P11: 12 | Q11: 18 | R11: 14 | S11: 31 | T11: =F11-H11 -> 68 | U11: =G11-I11 -> 117
A12: 10 | B12: Aaliyah Edwards | C12: 8 | D12: 155 | E12: 178 | F12: 74 | G12: 128 | H12: 1 | I12: 2 | J12: 17 | K12: 24 | L12: 35 | M12: 74 | N12: 109 | O12: 15 | P12: 7 | Q12: 4 | R12: 30 | S12: 29 | T12: =F12-H12 -> 73 | U12: =G12-I12 -> 126
A13: 11 | B13: Kelsey Mitchell | C13: 10 | D13: 179 | E13: 174 | F13: 74 | G13: 143 | H13: 18 | I13: 48 | J13: 5 | K13: 9 | L13: 6 | M13: 24 | N13: 30 | O13: 21 | P13: 10 | Q13: 2 | R13: 10 | S13: 25 | T13: =F13-H13 -> 56 | U13: =G13-I13 -> 95
A14: 12 | B14: Rhyne Howard | C14: 10 | D14: 204 | E14: 170 | F14: 58 | G14: 149 | H14: 29 | I14: 81 | J14: 15 | K14: 18 | L14: 6 | M14: 40 | N14: 46 | O14: 30 | P14: 13 | Q14: 7 | R14: 12 | S14: 23 | T14: =F14-H14 -> 29 | U14: =G14-I14 -> 68
... A51: 49 | B51: Aari McDonald | C51: 1 | D51: 6 | E51: 2 | F51: 0 | G51: 4 | H51: 0 | I51: 1 | J51: 1 | K51: 3 | L51: 1 | M51: 0 | N51: 1 | O51: 0 | P51: 0 | Q51: 0 | R51: 0 | S51: 2 | T51: =F51-H51 -> 0 | U51: =G51-I51 -> 3
B80: SOMME | C80: =SUM(C3:C49) -> 436 | D80: =SUM(D3:D49) -> 5884 | E80: =SUM(E3:E49) -> 5620 | F80: =SUM(F3:F49) -> 2158 | G80: =SUM(G3:G49) -> 4605 | H80: =SUM(H3:H49) -> 466 | I80: =SUM(I3:I49) -> 1441 | J80: =SUM(J3:J49) -> 467 | ... U80: =SUM(U3:U49) -> 3164
B81: TS Moy | C81: =100*(E80)/(2*(G80+0.44*K80)) -> 57.691202
B82: PPP Moy | C82: =(E80)/((G80+0.44*K80+R80)) -> 1.0293493
B83: 3P% Moy | C83: =100*(H80/I80) -> 32.338654
B84: 2P% Moy | C84: =100*(T80/U80) -> 53.476612
B85: FG% Moy | C85: =100*(F80/G80) -> 46.862106
B86: EFG% Moy | C86: =100*(F80+0.5*H80)/(G80) -> 51.921824
B87: FT% Moy | C87: =100*(J80/K80) -> 77.317881

Sheet PER_GAME_BASIC
A1: DATA | AM1: CENTILE
A2: Rank | B2: Player | C2: G | D2: MP | E2: PTS | F2: FG | G2: FGA | H2: FG% | I2: 3P | J2: 3PA | K2: 3P% | L2: FT | M2: FTA | N2: FT% | O2: ORB | P2: DRB | Q2: TRB | R2: AST | S2: STL | T2: BLK | U2: TOV | V2: PF | W2: 2P | X2: 2PA | Y2: 2P% | Z2: AST/TO | AA2: TS% | AB2: PPS | AC2: PPP | AD2: EFG% | AE2: TS+ | AF2: PPP+ | AG2: FT+ | AH2: EFG+ | AI2: BLK/PF | AJ2: TOV% | AM2: MP | AN2: PTS | AO2: FG | AP2: FGA | AQ2: FG% | AR2: 3P | AS2: 3PA | AT2: 3P% | AU2: FT | AV2: FTA | AW2: FT% | AX2: ORB | AY2: DRB | AZ2: TRB | BA2: AST | BB2: STL | BC2: BLK | BD2: TOV | BE2: PF | BF2: 2P | BG2: 2PA | BH2: 2P% | BI2: AST/TO | BJ2: TS% | BK2: PPS | BL2: PPP | BM2: EFG% | BN2: BLK/PF | BO2: TOV%
A3: 1 | B3: Marina Mabrey | C3: 9 | D3: 21 | E3: 26.8 | F3: 9.8 | G3: 22.6 | H3: 43.3 | I3: 3.8 | J3: 11.6 | K3: 32.7 | L3: 2.1 | M3: 2.4 | N3: 86.4 | O3: 0.8 | P3: 6.6 | Q3: 7.3 | R3: 4.8 | S3: 0.4 | T3: 0.2 | U3: 3.4 | V3: 3.1 | W3: =F3-I3 -> 6 | X3: =G3-J3 -> 11 | Y3: =IF(X3=0,"0",(W3/X3)*100) -> 54.545455 | Z3: =IF(U3=0,"0",R3/U3) -> 1.4117647 | AA3: =100*(E3)/(2*(G3+0.44*M3)) -> 56.645249 | AB3: =2*AA3/100 -> 1.132905 | AC3: =(E3)/(G3+0.44*M3+U3) -> 0.99053814 | AD3: =100*(F3+0.5*I3)/(G3) -> 51.769912 | AE3: =100*(AA3/TOTAL_BASIC!$C$81) -> 98.186979 | AF3: =100*AC3/TOTAL_BASIC!$C$82 -> 96.229547 | AG3: =100*N3/TOTAL_BASIC!$C$87 -> 111.74647 | AH3: =100*AD3/TOTAL_BASIC!$C$86 -> 99.707421 | AI3: =T3/V3 -> 0.064516129 | AJ3: =100*(U3)/(G3+0.44*M3+U3) -> 12.566529 | AM3: =(PERCENTRANK(D$3:D$78,D3))*100 -> 97.9 | AN3: =(PERCENTRANK(E$3:E$78,E3))*100 -> 100 | AO3: =(PERCENTRANK(F$3:F$78,F3))*100 -> 100 | AP3: =(PERCENTRANK(G$3:G$78,G3))*100 -> 100 | AQ3: =(PERCENTRANK(H$3:H$78,H3))*100 -> 37.5 | AR3: =(PERCENTRANK(I$3:I$78,I3))*100 -> 100 | AS3: =(PERCENTRANK(J$3:J$78,J3))*100 -> 100 | AT3: =(PERCENTRANK(K$3:K$78,K3))*100 -> 58.3 | ... BC3: =(PERCENTRANK(T$3:T$78,T3))*100 -> 25 | BD3: =100-(PERCENTRANK(U$3:U$78,U3))*100 -> 2.1 | BE3: =100-(PERCENTRANK(V$3:V$78,V3))*100 -> 20.9 | BF3: =(PERCENTRANK(W$3:W$78,W3))*100 -> 85.4 | BG3: =(PERCENTRANK(X$3:X$78,X3))*100 -> 89.5 | BH3: =(PERCENTRANK(Y$3:Y$78,Y3))*100 -> 56.2 | BI3: =(PERCENTRANK(Z$3:Z$78,Z3))*100 -> 50 | BJ3: =(PERCENTRANK(AA$3:AA$78,AA3))*100 -> 45.8 | BK3: =(PERCENTRANK(AB$3:AB$78,AB3))*100 -> 45.8 | BL3: =(PERCENTRANK(AC$3:AC$78,AC3))*100 -> 39.5 | BM3: =(PERCENTRANK(AD$3:AD$78,AD3))*100 -> 52 | BN3: =(PERCENTRANK(AI$3:AI$78,AI3))*100 -> 25 | BO3: =100-((PERCENTRANK(AJ$3:AJ$78,AJ3))*100) -> 25
A4: 2 | B4: Chelsea Gray | C4: 10 | D4: 22.5 | E4: 25.9 | F4: 9.1 | G4: 17.8 | H4: 51.1 | I4: 3.4 | J4: 7.3 | K4: 46.6 | L4: 2.1 | M4: 2.2 | N4: 95.5 | O4: 0.7 | P4: 5 | Q4: 5.7 | R4: 6.8 | S4: 1.6 | T4: 0.5 | U4: 2.3 | V4: 2.3 | W4: =F4-I4 -> 5.7 | X4: =G4-J4 -> 10.5 | Y4: =IF(X4=0,"0",(W4/X4)*100) -> 54.285714 | Z4: =IF(U4=0,"0",R4/U4) -> 2.9565217 | AA4: =100*(E4)/(2*(G4+0.44*M4)) -> 69.000426 | AB4: =2*AA4/100 -> 1.3800085 | AC4: =(E4)/(G4+0.44*M4+U4) -> 1.2293526 | AD4: =100*(F4+0.5*I4)/(G4) -> 60.674157 | AE4: =100*(AA4/TOTAL_BASIC!$C$81) -> 119.60303 | AF4: =100*AC4/TOTAL_BASIC!$C$82 -> 119.43007 | AG4: =100*N4/TOTAL_BASIC!$C$87 -> 123.51606 | AH4: =100*AD4/TOTAL_BASIC!$C$86 -> 116.85675 | AI4: =T4/V4 -> 0.2173913 | AJ4: =100*(U4)/(G4+0.44*M4+U4) -> 10.917031 | AM4: =(PERCENTRANK(D$3:D$78,D4))*100 -> 100 | AN4: =(PERCENTRANK(E$3:E$78,E4))*100 -> 97.9 | AO4: =(PERCENTRANK(F$3:F$78,F4))*100 -> 93.7 | AP4: =(PERCENTRANK(G$3:G$78,G4))*100 -> 97.9 | AQ4: =(PERCENTRANK(H$3:H$78,H4))*100 -> 77 | AR4: =(PERCENTRANK(I$3:I$78,I4))*100 -> 97.9 | AS4: =(PERCENTRANK(J$3:J$78,J4))*100 -> 95.8 | AT4: =(PERCENTRANK(K$3:K$78,K4))*100 -> 97.9 | ... BC4: =(PERCENTRANK(T$3:T$78,T4))*100 -> 60.4 | BD4: =100-(PERCENTRANK(U$3:U$78,U4))*100 -> 8.4 | BE4: =100-(PERCENTRANK(V$3:V$78,V4))*100 -> 54.2 | BF4: =(PERCENTRANK(W$3:W$78,W4))*100 -> 83.3 | BG4: =(PERCENTRANK(X$3:X$78,X4))*100 -> 81.2 | BH4: =(PERCENTRANK(Y$3:Y$78,Y4))*100 -> 52 | BI4: =(PERCENTRANK(Z$3:Z$78,Z4))*100 -> 86.9 | BJ4: =(PERCENTRANK(AA$3:AA$78,AA4))*100 -> 95.8 | BK4: =(PERCENTRANK(AB$3:AB$78,AB4))*100 -> 95.8 | BL4: =(PERCENTRANK(AC$3:AC$78,AC4))*100 -> 97.9 | BM4: =(PERCENTRANK(AD$3:AD$78,AD4))*100 -> 95.8 | BN4: =(PERCENTRANK(AI$3:AI$78,AI4))*100 -> 62.5 | BO4: =100-((PERCENTRANK(AJ$3:AJ$78,AJ4))*100) -> 50
A5: 3 | B5: Paige Bueckers | C5: 10 | D5: 20.6 | E5: 25 | F5: 9.6 | G5: 17.3 | H5: 55.5 | I5: 1.5 | J5: 3.8 | K5: 39.5 | L5: 2.7 | M5: 3 | N5: 90 | O5: 0.5 | P5: 5.8 | Q5: 6.3 | R5: 6.7 | S5: 0.9 | T5: 0.6 | U5: 2.4 | V5: 2.9 | W5: =F5-I5 -> 8.1 | X5: =G5-J5 -> 13.5 | Y5: =IF(X5=0,"0",(W5/X5)*100) -> 60 | Z5: =IF(U5=0,"0",R5/U5) -> 2.7916667 | AA5: =100*(E5)/(2*(G5+0.44*M5)) -> 67.132116 | AB5: =2*AA5/100 -> 1.3426423 | AC5: =(E5)/(G5+0.44*M5+U5) -> 1.1893435 | AD5: =100*(F5+0.5*I5)/(G5) -> 59.82659 | AE5: =100*(AA5/TOTAL_BASIC!$C$81) -> 116.36456 | AF5: =100*AC5/TOTAL_BASIC!$C$82 -> 115.54324 | AG5: =100*N5/TOTAL_BASIC!$C$87 -> 116.40257 | AH5: =100*AD5/TOTAL_BASIC!$C$86 -> 115.22436 | AI5: =T5/V5 -> 0.20689655 | AJ5: =100*(U5)/(G5+0.44*M5+U5) -> 11.417697 | AM5: =(PERCENTRANK(D$3:D$78,D5))*100 -> 95.8 | AN5: =(PERCENTRANK(E$3:E$78,E5))*100 -> 95.8 | AO5: =(PERCENTRANK(F$3:F$78,F5))*100 -> 97.9 | AP5: =(PERCENTRANK(G$3:G$78,G5))*100 -> 95.8 | AQ5: =(PERCENTRANK(H$3:H$78,H5))*100 -> 89.5 | AR5: =(PERCENTRANK(I$3:I$78,I5))*100 -> 75 | AS5: =(PERCENTRANK(J$3:J$78,J5))*100 -> 66.6 | AT5: =(PERCENTRANK(K$3:K$78,K5))*100 -> 87.5 | ... BC5: =(PERCENTRANK(T$3:T$78,T5))*100 -> 70.8 | BD5: =100-(PERCENTRANK(U$3:U$78,U5))*100 -> 6.3 | BE5: =100-(PERCENTRANK(V$3:V$78,V5))*100 -> 29.2 | BF5: =(PERCENTRANK(W$3:W$78,W5))*100 -> 97.9 | BG5: =(PERCENTRANK(X$3:X$78,X5))*100 -> 97.9 | BH5: =(PERCENTRANK(Y$3:Y$78,Y5))*100 -> 83.3 | BI5: =(PERCENTRANK(Z$3:Z$78,Z5))*100 -> 82.6 | BJ5: =(PERCENTRANK(AA$3:AA$78,AA5))*100 -> 93.7 | BK5: =(PERCENTRANK(AB$3:AB$78,AB5))*100 -> 93.7 | BL5: =(PERCENTRANK(AC$3:AC$78,AC5))*100 -> 91.6 | BM5: =(PERCENTRANK(AD$3:AD$78,AD5))*100 -> 93.7 | BN5: =(PERCENTRANK(AI$3:AI$78,AI5))*100 -> 58.3 | BO5: =100-((PERCENTRANK(AJ$3:AJ$78,AJ5))*100) -> 43.8
A6: 4 | B6: Aaliyah Edwards | C6: 8 | D6: 19.4 | E6: 22.3 | F6: 9.3 | G6: 16 | H6: 57.8 | I6: 0.1 | J6: 0.3 | K6: 50 | L6: 2.1 | M6: 3 | N6: 70.8 | O6: 4.4 | P6: 9.3 | Q6: 13.6 | R6: 1.9 | S6: 0.9 | T6: 0.5 | U6: 3.8 | V6: 3.6 | W6: =F6-I6 -> 9.2 | X6: =G6-J6 -> 15.7 | Y6: =IF(X6=0,"0",(W6/X6)*100) -> 58.598726 | Z6: =IF(U6=0,"0",R6/U6) -> 0.5 | AA6: =100*(E6)/(2*(G6+0.44*M6)) -> 64.376443 | AB6: =2*AA6/100 -> 1.2875289 | AC6: =(E6)/(G6+0.44*M6+U6) -> 1.0558712 | AD6: =100*(F6+0.5*I6)/(G6) -> 58.4375 | AE6: =100*(AA6/TOTAL_BASIC!$C$81) -> 111.58797 | AF6: =100*AC6/TOTAL_BASIC!$C$82 -> 102.57657 | AG6: =100*N6/TOTAL_BASIC!$C$87 -> 91.570021 | AH6: =100*AD6/TOTAL_BASIC!$C$86 -> 112.54901 | AI6: =T6/V6 -> 0.13888889 | AJ6: =100*(U6)/(G6+0.44*M6+U6) -> 17.992424 | AM6: =(PERCENTRANK(D$3:D$78,D6))*100 -> 89.5 | AN6: =(PERCENTRANK(E$3:E$78,E6))*100 -> 93.7 | AO6: =(PERCENTRANK(F$3:F$78,F6))*100 -> 95.8 | AP6: =(PERCENTRANK(G$3:G$78,G6))*100 -> 89.5 | AQ6: =(PERCENTRANK(H$3:H$78,H6))*100 -> 95.8 | AR6: =(PERCENTRANK(I$3:I$78,I6))*100 -> 10.4 | AS6: =(PERCENTRANK(J$3:J$78,J6))*100 -> 6.2 | AT6: =(PERCENTRANK(K$3:K$78,K6))*100 -> 100 | ... BC6: =(PERCENTRANK(T$3:T$78,T6))*100 -> 60.4 | BD6: =100-(PERCENTRANK(U$3:U$78,U6))*100 -> 0 | BE6: =100-(PERCENTRANK(V$3:V$78,V6))*100 -> 4.2 | BF6: =(PERCENTRANK(W$3:W$78,W6))*100 -> 100 | BG6: =(PERCENTRANK(X$3:X$78,X6))*100 -> 100 | BH6: =(PERCENTRANK(Y$3:Y$78,Y6))*100 -> 70.8 | BI6: =(PERCENTRANK(Z$3:Z$78,Z6))*100 -> 8.6 | BJ6: =(PERCENTRANK(AA$3:AA$78,AA6))*100 -> 91.6 | BK6: =(PERCENTRANK(AB$3:AB$78,AB6))*100 -> 91.6 | BL6: =(PERCENTRANK(AC$3:AC$78,AC6))*100 -> 68.7 | BM6: =(PERCENTRANK(AD$3:AD$78,AD6))*100 -> 89.5 | BN6: =(PERCENTRANK(AI$3:AI$78,AI6))*100 -> 47.9 | BO6: =100-((PERCENTRANK(AJ$3:AJ$78,AJ6))*100) -> 4.2
A7: 5 | B7: Kelsey Plum | C7: 10 | D7: 18.6 | E7: 21.6 | F7: 8.2 | G7: 16.7 | H7: 49.1 | I7: 2.7 | J7: 7.1 | K7: 38 | L7: 1.6 | M7: 1.6 | N7: 100 | O7: 0.9 | P7: 4.6 | Q7: 5.5 | R7: 5.6 | S7: 0.3 | T7: 0.1 | U7: 1.5 | V7: 3.2 | W7: =F7-I7 -> 5.5 | X7: =G7-J7 -> 9.6 | Y7: =IF(X7=0,"0",(W7/X7)*100) -> 57.291667 | Z7: =IF(U7=0,"0",R7/U7) -> 3.7333333 | AA7: =100*(E7)/(2*(G7+0.44*M7)) -> 62.0547 | AB7: =2*AA7/100 -> 1.241094 | AC7: =(E7)/(G7+0.44*M7+U7) -> 1.1426153 | AD7: =100*(F7+0.5*I7)/(G7) -> 57.185629 | AE7: =100*(AA7/TOTAL_BASIC!$C$81) -> 107.56354 | AF7: =100*AC7/TOTAL_BASIC!$C$82 -> 111.00366 | AG7: =100*N7/TOTAL_BASIC!$C$87 -> 129.33619 | AH7: =100*AD7/TOTAL_BASIC!$C$86 -> 110.13794 | AI7: =T7/V7 -> 0.03125 | AJ7: =100*(U7)/(G7+0.44*M7+U7) -> 7.9348286 | AM7: =(PERCENTRANK(D$3:D$78,D7))*100 -> 87.5 | AN7: =(PERCENTRANK(E$3:E$78,E7))*100 -> 91.6 | AO7: =(PERCENTRANK(F$3:F$78,F7))*100 -> 91.6 | AP7: =(PERCENTRANK(G$3:G$78,G7))*100 -> 93.7 | AQ7: =(PERCENTRANK(H$3:H$78,H7))*100 -> 68.7 | AR7: =(PERCENTRANK(I$3:I$78,I7))*100 -> 93.7 | AS7: =(PERCENTRANK(J$3:J$78,J7))*100 -> 93.7 | AT7: =(PERCENTRANK(K$3:K$78,K7))*100 -> 81.2 | ... BC7: =(PERCENTRANK(T$3:T$78,T7))*100 -> 14.5 | BD7: =100-(PERCENTRANK(U$3:U$78,U7))*100 -> 31.3 | BE7: =100-(PERCENTRANK(V$3:V$78,V7))*100 -> 14.6 | BF7: =(PERCENTRANK(W$3:W$78,W7))*100 -> 75 | BG7: =(PERCENTRANK(X$3:X$78,X7))*100 -> 72.9 | BH7: =(PERCENTRANK(Y$3:Y$78,Y7))*100 -> 64.5 | BI7: =(PERCENTRANK(Z$3:Z$78,Z7))*100 -> 93.4 | BJ7: =(PERCENTRANK(AA$3:AA$78,AA7))*100 -> 81.2 | BK7: =(PERCENTRANK(AB$3:AB$78,AB7))*100 -> 81.2 | BL7: =(PERCENTRANK(AC$3:AC$78,AC7))*100 -> 85.4 | BM7: =(PERCENTRANK(AD$3:AD$78,AD7))*100 -> 83.3 | BN7: =(PERCENTRANK(AI$3:AI$78,AI7))*100 -> 14.5 | BO7: =100-((PERCENTRANK(AJ$3:AJ$78,AJ7))*100) -> 75
A8: 6 | B8: Kahleah Copper | C8: 7 | D8: 18 | E8: 20.3 | F8: 7.9 | G8: 16.3 | H8: 48.2 | I8: 2.3 | J8: 5.7 | K8: 40 | L8: 1.3 | M8: 1.7 | N8: 75 | O8: 1 | P8: 3.6 | Q8: 4.6 | R8: 0.6 | S8: 0.1 | T8: 0.3 | U8: 0.6 | V8: 3.6 | W8: =F8-I8 -> 5.6 | X8: =G8-J8 -> 10.6 | Y8: =IF(X8=0,"0",(W8/X8)*100) -> 52.830189 | Z8: =IF(U8=0,"0",R8/U8) -> 1 | AA8: =100*(E8)/(2*(G8+0.44*M8)) -> 59.537776 | AB8: =2*AA8/100 -> 1.1907555 | AC8: =(E8)/(G8+0.44*M8+U8) -> 1.150272 | AD8: =100*(F8+0.5*I8)/(G8) -> 55.521472 | AE8: =100*(AA8/TOTAL_BASIC!$C$81) -> 103.20079 | AF8: =100*AC8/TOTAL_BASIC!$C$82 -> 111.74749 | AG8: =100*N8/TOTAL_BASIC!$C$87 -> 97.002141 | AH8: =100*AD8/TOTAL_BASIC!$C$86 -> 106.93282 | AI8: =T8/V8 -> 0.083333333 | AJ8: =100*(U8)/(G8+0.44*M8+U8) -> 3.3998187 | AM8: =(PERCENTRANK(D$3:D$78,D8))*100 -> 85.4 | AN8: =(PERCENTRANK(E$3:E$78,E8))*100 -> 89.5 | AO8: =(PERCENTRANK(F$3:F$78,F8))*100 -> 89.5 | AP8: =(PERCENTRANK(G$3:G$78,G8))*100 -> 91.6 | AQ8: =(PERCENTRANK(H$3:H$78,H8))*100 -> 62.5 | AR8: =(PERCENTRANK(I$3:I$78,I8))*100 -> 91.6 | AS8: =(PERCENTRANK(J$3:J$78,J8))*100 -> 89.5 | AT8: =(PERCENTRANK(K$3:K$78,K8))*100 -> 89.5 | ... BC8: =(PERCENTRANK(T$3:T$78,T8))*100 -> 37.5 | BD8: =100-(PERCENTRANK(U$3:U$78,U8))*100 -> 89.6 | BE8: =100-(PERCENTRANK(V$3:V$78,V8))*100 -> 4.2 | BF8: =(PERCENTRANK(W$3:W$78,W8))*100 -> 79.1 | BG8: =(PERCENTRANK(X$3:X$78,X8))*100 -> 83.3 | BH8: =(PERCENTRANK(Y$3:Y$78,Y8))*100 -> 47.9 | BI8: =(PERCENTRANK(Z$3:Z$78,Z8))*100 -> 39.1 | BJ8: =(PERCENTRANK(AA$3:AA$78,AA8))*100 -> 75 | BK8: =(PERCENTRANK(AB$3:AB$78,AB8))*100 -> 75 | BL8: =(PERCENTRANK(AC$3:AC$78,AC8))*100 -> 87.5 | BM8: =(PERCENTRANK(AD$3:AD$78,AD8))*100 -> 75 | BN8: =(PERCENTRANK(AI$3:AI$78,AI8))*100 -> 29.1 | BO8: =100-((PERCENTRANK(AJ$3:AJ$78,AJ8))*100) -> 95.9
A9: 7 | B9: Breanna Stewart | C9: 10 | D9: 16.8 | E9: 20.1 | F9: 7.6 | G9: 15.7 | H9: 48.4 | I9: 0.9 | J9: 3.7 | K9: 24.3 | L9: 2.3 | M9: 2.7 | N9: 85.2 | O9: 1.5 | P9: 7.7 | Q9: 9.2 | R9: 2.6 | S9: 1.1 | T9: 0.6 | U9: 1.8 | V9: 1.9 | W9: =F9-I9 -> 6.7 | X9: =G9-J9 -> 12 | Y9: =IF(X9=0,"0",(W9/X9)*100) -> 55.833333 | Z9: =IF(U9=0,"0",R9/U9) -> 1.4444444 | AA9: =100*(E9)/(2*(G9+0.44*M9)) -> 59.509711 | AB9: =2*AA9/100 -> 1.1901942 | AC9: =(E9)/(G9+0.44*M9+U9) -> 1.0755565 | AD9: =100*(F9+0.5*I9)/(G9) -> 51.273885 | AE9: =100*(AA9/TOTAL_BASIC!$C$81) -> 103.15214 | AF9: =100*AC9/TOTAL_BASIC!$C$82 -> 104.48897 | AG9: =100*N9/TOTAL_BASIC!$C$87 -> 110.19443 | AH9: =100*AD9/TOTAL_BASIC!$C$86 -> 98.752088 | AI9: =T9/V9 -> 0.31578947 | AJ9: =100*(U9)/(G9+0.44*M9+U9) -> 9.6318493 | AM9: =(PERCENTRANK(D$3:D$78,D9))*100 -> 77 | AN9: =(PERCENTRANK(E$3:E$78,E9))*100 -> 85.4 | AO9: =(PERCENTRANK(F$3:F$78,F9))*100 -> 83.3 | AP9: =(PERCENTRANK(G$3:G$78,G9))*100 -> 85.4 | AQ9: =(PERCENTRANK(H$3:H$78,H9))*100 -> 64.5 | AR9: =(PERCENTRANK(I$3:I$78,I9))*100 -> 50 | AS9: =(PERCENTRANK(J$3:J$78,J9))*100 -> 62.5 | AT9: =(PERCENTRANK(K$3:K$78,K9))*100 -> 35.4 | ... BC9: =(PERCENTRANK(T$3:T$78,T9))*100 -> 70.8 | BD9: =100-(PERCENTRANK(U$3:U$78,U9))*100 -> 18.8 | BE9: =100-(PERCENTRANK(V$3:V$78,V9))*100 -> 77.1 | BF9: =(PERCENTRANK(W$3:W$78,W9))*100 -> 91.6 | BG9: =(PERCENTRANK(X$3:X$78,X9))*100 -> 93.7 | BH9: =(PERCENTRANK(Y$3:Y$78,Y9))*100 -> 58.3 | BI9: =(PERCENTRANK(Z$3:Z$78,Z9))*100 -> 52.1 | BJ9: =(PERCENTRANK(AA$3:AA$78,AA9))*100 -> 72.9 | BK9: =(PERCENTRANK(AB$3:AB$78,AB9))*100 -> 72.9 | BL9: =(PERCENTRANK(AC$3:AC$78,AC9))*100 -> 70.8 | BM9: =(PERCENTRANK(AD$3:AD$78,AD9))*100 -> 45.8 | BN9: =(PERCENTRANK(AI$3:AI$78,AI9))*100 -> 77 | BO9: =100-((PERCENTRANK(AJ$3:AJ$78,AJ9))*100) -> 62.5
A10: 8 | B10: Allisha Gray | C10: 10 | D10: 15.8 | E10: 20.1 | F10: 6.8 | G10: 15.8 | H10: 43 | I10: 2.2 | J10: 6.7 | K10: 32.8 | L10: 2.2 | M10: 2.6 | N10: 84.6 | O10: 0.9 | P10: 3.4 | Q10: 4.3 | R10: 3 | S10: 0.9 | T10: 0.8 | U10: 1.6 | V10: 1.8 | W10: =F10-I10 -> 4.6 | X10: =G10-J10 -> 9.1 | Y10: =IF(X10=0,"0",(W10/X10)*100) -> 50.549451 | Z10: =IF(U10=0,"0",R10/U10) -> 1.875 | AA10: =100*(E10)/(2*(G10+0.44*M10)) -> 59.313031 | AB10: =2*AA10/100 -> 1.1862606 | AC10: =(E10)/(G10+0.44*M10+U10) -> 1.0839085 | AD10: =100*(F10+0.5*I10)/(G10) -> 50 | AE10: =100*(AA10/TOTAL_BASIC!$C$81) -> 102.81122 | AF10: =100*AC10/TOTAL_BASIC!$C$82 -> 105.30036 | AG10: =100*N10/TOTAL_BASIC!$C$87 -> 109.41842 | AH10: =100*AD10/TOTAL_BASIC!$C$86 -> 96.29862 | AI10: =T10/V10 -> 0.44444444 | AJ10: =100*(U10)/(G10+0.44*M10+U10) -> 8.6281277 | AM10: =(PERCENTRANK(D$3:D$78,D10))*100 -> 66.6 | AN10: =(PERCENTRANK(E$3:E$78,E10))*100 -> 85.4 | AO10: =(PERCENTRANK(F$3:F$78,F10))*100 -> 77 | AP10: =(PERCENTRANK(G$3:G$78,G10))*100 -> 87.5 | AQ10: =(PERCENTRANK(H$3:H$78,H10))*100 -> 35.4 | AR10: =(PERCENTRANK(I$3:I$78,I10))*100 -> 87.5 | AS10: =(PERCENTRANK(J$3:J$78,J10))*100 -> 91.6 | AT10: =(PERCENTRANK(K$3:K$78,K10))*100 -> 60.4 | ... BC10: =(PERCENTRANK(T$3:T$78,T10))*100 -> 79.1 | BD10: =100-(PERCENTRANK(U$3:U$78,U10))*100 -> 27.1 | BE10: =100-(PERCENTRANK(V$3:V$78,V10))*100 -> 81.3 | BF10: =(PERCENTRANK(W$3:W$78,W10))*100 -> 66.6 | BG10: =(PERCENTRANK(X$3:X$78,X10))*100 -> 64.5 | BH10: =(PERCENTRANK(Y$3:Y$78,Y10))*100 -> 43.7 | BI10: =(PERCENTRANK(Z$3:Z$78,Z10))*100 -> 56.5 | BJ10: =(PERCENTRANK(AA$3:AA$78,AA10))*100 -> 70.8 | BK10: =(PERCENTRANK(AB$3:AB$78,AB10))*100 -> 70.8 | BL10: =(PERCENTRANK(AC$3:AC$78,AC10))*100 -> 72.9 | BM10: =(PERCENTRANK(AD$3:AD$78,AD10))*100 -> 39.5 | BN10: =(PERCENTRANK(AI$3:AI$78,AI10))*100 -> 89.5 | BO10: =100-((PERCENTRANK(AJ$3:AJ$78,AJ10))*100) -> 68.8
A11: 9 | B11: Dearica Hamby | C11: 10 | D11: 15.8 | E11: 19.2 | F11: 7.8 | G11: 13.8 | H11: 56.5 | I11: 0.3 | J11: 1.4 | K11: 21.4 | L11: 1.8 | M11: 3 | N11: 60 | O11: 1.8 | P11: 6.5 | Q11: 8.3 | R11: 0.8 | S11: 0.7 | T11: 0 | U11: 1 | V11: 3.3 | W11: =F11-I11 -> 7.5 | X11: =G11-J11 -> 12.4 | Y11: =IF(X11=0,"0",(W11/X11)*100) -> 60.483871 | Z11: =IF(U11=0,"0",R11/U11) -> 0.8 | AA11: =100*(E11)/(2*(G11+0.44*M11)) -> 63.492063 | AB11: =2*AA11/100 -> 1.2698413 | AC11: =(E11)/(G11+0.44*M11+U11) -> 1.191067 | AD11: =100*(F11+0.5*I11)/(G11) -> 57.608696 | AE11: =100*(AA11/TOTAL_BASIC!$C$81) -> 110.05502 | AF11: =100*AC11/TOTAL_BASIC!$C$82 -> 115.71068 | AG11: =100*N11/TOTAL_BASIC!$C$87 -> 77.601713 | AH11: =100*AD11/TOTAL_BASIC!$C$86 -> 110.95276 | AI11: =T11/V11 -> 0 | AJ11: =100*(U11)/(G11+0.44*M11+U11) -> 6.2034739 | AM11: =(PERCENTRANK(D$3:D$78,D11))*100 -> 66.6 | AN11: =(PERCENTRANK(E$3:E$78,E11))*100 -> 83.3 | AO11: =(PERCENTRANK(F$3:F$78,F11))*100 -> 85.4 | AP11: =(PERCENTRANK(G$3:G$78,G11))*100 -> 68.7 | AQ11: =(PERCENTRANK(H$3:H$78,H11))*100 -> 91.6 | AR11: =(PERCENTRANK(I$3:I$78,I11))*100 -> 22.9 | AS11: =(PERCENTRANK(J$3:J$78,J11))*100 -> 18.7 | AT11: =(PERCENTRANK(K$3:K$78,K11))*100 -> 27 | ... BC11: =(PERCENTRANK(T$3:T$78,T11))*100 -> 0 | BD11: =100-(PERCENTRANK(U$3:U$78,U11))*100 -> 70.9 | BE11: =100-(PERCENTRANK(V$3:V$78,V11))*100 -> 10.5 | BF11: =(PERCENTRANK(W$3:W$78,W11))*100 -> 95.8 | BG11: =(PERCENTRANK(X$3:X$78,X11))*100 -> 95.8 | BH11: =(PERCENTRANK(Y$3:Y$78,Y11))*100 -> 89.5 | BI11: =(PERCENTRANK(Z$3:Z$78,Z11))*100 -> 30.4 | BJ11: =(PERCENTRANK(AA$3:AA$78,AA11))*100 -> 87.5 | BK11: =(PERCENTRANK(AB$3:AB$78,AB11))*100 -> 87.5 | BL11: =(PERCENTRANK(AC$3:AC$78,AC11))*100 -> 93.7 | BM11: =(PERCENTRANK(AD$3:AD$78,AD11))*100 -> 85.4 | BN11: =(PERCENTRANK(AI$3:AI$78,AI11))*100 -> 0 | BO11: =100-((PERCENTRANK(AJ$3:AJ$78,AJ11))*100) -> 89.6
A12: 10 | B12: Brittney Sykes | C12: 10 | D12: 15.4 | E12: 18.9 | F12: 6.9 | G12: 14.5 | H12: 47.6 | I12: 2.2 | J12: 5.2 | K12: 42.3 | L12: 1.6 | M12: 2.1 | N12: 76.2 | O12: 0.4 | P12: 3.4 | Q12: 3.8 | R12: 1.7 | S12: 1.6 | T12: 0.3 | U12: 2 | V12: 3.2 | W12: =F12-I12 -> 4.7 | X12: =G12-J12 -> 9.3 | Y12: =IF(X12=0,"0",(W12/X12)*100) -> 50.537634 | Z12: =IF(U12=0,"0",R12/U12) -> 0.85 | AA12: =100*(E12)/(2*(G12+0.44*M12)) -> 61.268154 | AB12: =2*AA12/100 -> 1.2253631 | AC12: =(E12)/(G12+0.44*M12+U12) -> 1.0847107 | AD12: =100*(F12+0.5*I12)/(G12) -> 55.172414 | AE12: =100*(AA12/TOTAL_BASIC!$C$81) -> 106.20017 | AF12: =100*AC12/TOTAL_BASIC!$C$82 -> 105.3783 | AG12: =100*N12/TOTAL_BASIC!$C$87 -> 98.554176 | AH12: =100*AD12/TOTAL_BASIC!$C$86 -> 106.26055 | AI12: =T12/V12 -> 0.09375 | AJ12: =100*(U12)/(G12+0.44*M12+U12) -> 11.478421 | AM12: =(PERCENTRANK(D$3:D$78,D12))*100 -> 64.5 | AN12: =(PERCENTRANK(E$3:E$78,E12))*100 -> 81.2 | AO12: =(PERCENTRANK(F$3:F$78,F12))*100 -> 79.1 | AP12: =(PERCENTRANK(G$3:G$78,G12))*100 -> 77 | AQ12: =(PERCENTRANK(H$3:H$78,H12))*100 -> 60.4 | AR12: =(PERCENTRANK(I$3:I$78,I12))*100 -> 87.5 | AS12: =(PERCENTRANK(J$3:J$78,J12))*100 -> 87.5 | AT12: =(PERCENTRANK(K$3:K$78,K12))*100 -> 95.8 | ... BC12: =(PERCENTRANK(T$3:T$78,T12))*100 -> 37.5 | BD12: =100-(PERCENTRANK(U$3:U$78,U12))*100 -> 10.5 | BE12: =100-(PERCENTRANK(V$3:V$78,V12))*100 -> 14.6 | BF12: =(PERCENTRANK(W$3:W$78,W12))*100 -> 68.7 | BG12: =(PERCENTRANK(X$3:X$78,X12))*100 -> 68.7 | BH12: =(PERCENTRANK(Y$3:Y$78,Y12))*100 -> 41.6 | BI12: =(PERCENTRANK(Z$3:Z$78,Z12))*100 -> 32.6 | BJ12: =(PERCENTRANK(AA$3:AA$78,AA12))*100 -> 79.1 | BK12: =(PERCENTRANK(AB$3:AB$78,AB12))*100 -> 79.1 | BL12: =(PERCENTRANK(AC$3:AC$78,AC12))*100 -> 75 | BM12: =(PERCENTRANK(AD$3:AD$78,AD12))*100 -> 70.8 | BN12: =(PERCENTRANK(AI$3:AI$78,AI12))*100 -> 31.2 | BO12: =100-((PERCENTRANK(AJ$3:AJ$78,AJ12))*100) -> 41.7
A13: 11 | B13: Aliyah Boston | C13: 10 | D13: 17.7 | E13: 18.6 | F13: 7.8 | G13: 14.9 | H13: 52.3 | I13: 1 | J13: 3.2 | K13: 31.3 | L13: 1.1 | M13: 1.5 | N13: 73.3 | O13: 1.9 | P13: 7.6 | Q13: 9.5 | R13: 2.6 | S13: 1.2 | T13: 1.8 | U13: 1.4 | V13: 3.1 | W13: =F13-I13 -> 6.8 | X13: =G13-J13 -> 11.7 | Y13: =IF(X13=0,"0",(W13/X13)*100) -> 58.119658 | Z13: =IF(U13=0,"0",R13/U13) -> 1.8571429 | AA13: =100*(E13)/(2*(G13+0.44*M13)) -> 59.768638 | AB13: =2*AA13/100 -> 1.1953728 | AC13: =(E13)/(G13+0.44*M13+U13) -> 1.0966981 | AD13: =100*(F13+0.5*I13)/(G13) -> 55.704698 | AE13: =100*(AA13/TOTAL_BASIC!$C$81) -> 103.60096 | AF13: =100*AC13/TOTAL_BASIC!$C$82 -> 106.54286 | AG13: =100*N13/TOTAL_BASIC!$C$87 -> 94.803426 | AH13: =100*AD13/TOTAL_BASIC!$C$86 -> 107.28571 | AI13: =T13/V13 -> 0.58064516 | AJ13: =100*(U13)/(G13+0.44*M13+U13) -> 8.254717 | AM13: =(PERCENTRANK(D$3:D$78,D13))*100 -> 81.2 | AN13: =(PERCENTRANK(E$3:E$78,E13))*100 -> 79.1 | AO13: =(PERCENTRANK(F$3:F$78,F13))*100 -> 85.4 | AP13: =(PERCENTRANK(G$3:G$78,G13))*100 -> 79.1 | AQ13: =(PERCENTRANK(H$3:H$78,H13))*100 -> 81.2 | AR13: =(PERCENTRANK(I$3:I$78,I13))*100 -> 58.3 | AS13: =(PERCENTRANK(J$3:J$78,J13))*100 -> 54.1 | AT13: =(PERCENTRANK(K$3:K$78,K13))*100 -> 56.2 | ... BC13: =(PERCENTRANK(T$3:T$78,T13))*100 -> 100 | BD13: =100-(PERCENTRANK(U$3:U$78,U13))*100 -> 39.6 | BE13: =100-(PERCENTRANK(V$3:V$78,V13))*100 -> 20.9 | BF13: =(PERCENTRANK(W$3:W$78,W13))*100 -> 93.7 | BG13: =(PERCENTRANK(X$3:X$78,X13))*100 -> 91.6 | BH13: =(PERCENTRANK(Y$3:Y$78,Y13))*100 -> 68.7 | BI13: =(PERCENTRANK(Z$3:Z$78,Z13))*100 -> 54.3 | BJ13: =(PERCENTRANK(AA$3:AA$78,AA13))*100 -> 77 | BK13: =(PERCENTRANK(AB$3:AB$78,AB13))*100 -> 77 | BL13: =(PERCENTRANK(AC$3:AC$78,AC13))*100 -> 79.1 | BM13: =(PERCENTRANK(AD$3:AD$78,AD13))*100 -> 77 | BN13: =(PERCENTRANK(AI$3:AI$78,AI13))*100 -> 97.9 | BO13: =100-((PERCENTRANK(AJ$3:AJ$78,AJ13))*100) -> 70.9
A14: 12 | B14: Kelsey Mitchell | C14: 10 | D14: 17.9 | E14: 17.4 | F14: 7.4 | G14: 14.3 | H14: 51.7 | I14: 1.8 | J14: 4.8 | K14: 37.5 | L14: 0.5 | M14: 0.9 | N14: 55.6 | O14: 0.6 | P14: 2.4 | Q14: 3 | R14: 2.1 | S14: 1 | T14: 0.2 | U14: 1 | V14: 2.5 | W14: =F14-I14 -> 5.6 | X14: =G14-J14 -> 9.5 | Y14: =IF(X14=0,"0",(W14/X14)*100) -> 58.947368 | Z14: =IF(U14=0,"0",R14/U14) -> 2.1 | AA14: =100*(E14)/(2*(G14+0.44*M14)) -> 59.199782 | AB14: =2*AA14/100 -> 1.1839956 | AC14: =(E14)/(G14+0.44*M14+U14) -> 1.1085627 | AD14: =100*(F14+0.5*I14)/(G14) -> 58.041958 | AE14: =100*(AA14/TOTAL_BASIC!$C$81) -> 102.61492 | AF14: =100*AC14/TOTAL_BASIC!$C$82 -> 107.69548 | AG14: =100*N14/TOTAL_BASIC!$C$87 -> 71.910921 | AH14: =100*AD14/TOTAL_BASIC!$C$86 -> 111.78721 | AI14: =T14/V14 -> 0.08 | AJ14: =100*(U14)/(G14+0.44*M14+U14) -> 6.3710499 | AM14: =(PERCENTRANK(D$3:D$78,D14))*100 -> 83.3 | AN14: =(PERCENTRANK(E$3:E$78,E14))*100 -> 77 | AO14: =(PERCENTRANK(F$3:F$78,F14))*100 -> 81.2 | AP14: =(PERCENTRANK(G$3:G$78,G14))*100 -> 75 | AQ14: =(PERCENTRANK(H$3:H$78,H14))*100 -> 79.1 | AR14: =(PERCENTRANK(I$3:I$78,I14))*100 -> 85.4 | AS14: =(PERCENTRANK(J$3:J$78,J14))*100 -> 77 | AT14: =(PERCENTRANK(K$3:K$78,K14))*100 -> 79.1 | ... BC14: =(PERCENTRANK(T$3:T$78,T14))*100 -> 25 | BD14: =100-(PERCENTRANK(U$3:U$78,U14))*100 -> 70.9 | BE14: =100-(PERCENTRANK(V$3:V$78,V14))*100 -> 41.7 | BF14: =(PERCENTRANK(W$3:W$78,W14))*100 -> 79.1 | BG14: =(PERCENTRANK(X$3:X$78,X14))*100 -> 70.8 | BH14: =(PERCENTRANK(Y$3:Y$78,Y14))*100 -> 75 | BI14: =(PERCENTRANK(Z$3:Z$78,Z14))*100 -> 60.8 | BJ14: =(PERCENTRANK(AA$3:AA$78,AA14))*100 -> 66.6 | BK14: =(PERCENTRANK(AB$3:AB$78,AB14))*100 -> 66.6 | BL14: =(PERCENTRANK(AC$3:AC$78,AC14))*100 -> 81.2 | BM14: =(PERCENTRANK(AD$3:AD$78,AD14))*100 -> 87.5 | BN14: =(PERCENTRANK(AI$3:AI$78,AI14))*100 -> 27 | BO14: =100-((PERCENTRANK(AJ$3:AJ$78,AJ14))*100) -> 85.5
... A51: 49 | B51: Aari McDonald | C51: 1 | D51: 6 | E51: 2 | F51: 0 | G51: 4 | H51: 0 | I51: 0 | J51: 1 | K51: 0 | L51: 1 | M51: 3 | N51: 33.3 | O51: 1 | P51: 0 | Q51: 1 | R51: 0 | S51: 0 | T51: 0 | U51: 0 | V51: 2 | W51: =F51-I51 -> 0 | X51: =G51-J51 -> 3 | Y51: =IF(X51=0,"0",(W51/X51)*100) -> 0 | Z51: =IF(U51=0,"0",R51/U51) -> 0 | AA51: =100*(E51)/(2*(G51+0.44*M51)) -> 18.796992 | AB51: =2*AA51/100 -> 0.37593985 | AC51: =(E51)/(G51+0.44*M51+U51) -> 0.37593985 | AD51: =100*(F51+0.5*I51)/(G51) -> 0 | AE51: =100*(AA51/TOTAL_BASIC!$C$81) -> 32.582078 | AF51: =100*AC51/TOTAL_BASIC!$C$82 -> 36.522088 | AG51: =100*N51/TOTAL_BASIC!$C$87 -> 43.068951 | AH51: =100*AD51/TOTAL_BASIC!$C$86 -> 0 | AI51: =T51/V51 -> 0 | AJ51: =100*(U51)/(G51+0.44*M51+U51) -> 0 | AM51: =(PERCENTRANK(D$3:D$78,D51))*100 -> 4.1 | AN51: =(PERCENTRANK(E$3:E$78,E51))*100 -> 0 | AO51: =(PERCENTRANK(F$3:F$78,F51))*100 -> 0 | AP51: =(PERCENTRANK(G$3:G$78,G51))*100 -> 6.2 | AQ51: =(PERCENTRANK(H$3:H$78,H51))*100 -> 0 | AR51: =(PERCENTRANK(I$3:I$78,I51))*100 -> 0 | AS51: =(PERCENTRANK(J$3:J$78,J51))*100 -> 12.5 | AT51: =(PERCENTRANK(K$3:K$78,K51))*100 -> 0 | ... BC51: =(PERCENTRANK(T$3:T$78,T51))*100 -> 0 | BD51: =100-(PERCENTRANK(U$3:U$78,U51))*100 -> 100 | BE51: =100-(PERCENTRANK(V$3:V$78,V51))*100 -> 75 | BF51: =(PERCENTRANK(W$3:W$78,W51))*100 -> 0 | BG51: =(PERCENTRANK(X$3:X$78,X51))*100 -> 12.5 | BH51: =(PERCENTRANK(Y$3:Y$78,Y51))*100 -> 0 | BI51: =(PERCENTRANK(Z$3:Z$78,Z51))*100 -> 0 | BJ51: =(PERCENTRANK(AA$3:AA$78,AA51))*100 -> 0 | BK51: =(PERCENTRANK(AB$3:AB$78,AB51))*100 -> 0 | BL51: =(PERCENTRANK(AC$3:AC$78,AC51))*100 -> 0 | BM51: =(PERCENTRANK(AD$3:AD$78,AD51))*100 -> 0 | BN51: =(PERCENTRANK(AI$3:AI$78,AI51))*100 -> 0 | BO51: =100-((PERCENTRANK(AJ$3:AJ$78,AJ51))*100) -> 100

Sheet ADVANCED
A1: DATA | I1: CENTILE
A2: Player | B2: AST% | C2: USG% | D2: AST:USG | E2: TOV% | F2: AST:TOV | I2: AST% | J2: USG% | K2: AST:USG | L2: TOV% | M2: AST:TOV
A3: Paige Bueckers | B3: 50.053944 | C3: 36.348351 | D3: 1.3770623 | E3: 11.417697 | F3: 4.3838913 | I3: =(PERCENTRANK(B$3:B$49,B3))*100 -> 100 | J3: =(PERCENTRANK(C$3:C$49,C3))*100 -> 63 | K3: =(PERCENTRANK(D$3:D$49,D3))*100 -> 97.8 | L3: =100-((PERCENTRANK(E$3:E$49,E3))*100) -> 43.5 | M3: =(PERCENTRANK(F$3:F$49,F3))*100 -> 93.4
A4: Dominique Malonga | B4: 8.1709896 | C4: 37.613008 | D4: 0.2172384 | E4: 15.568241 | F4: 0.5248499 | I4: =(PERCENTRANK(B$3:B$49,B4))*100 -> 15.2 | J4: =(PERCENTRANK(C$3:C$49,C4))*100 -> 78.2 | K4: =(PERCENTRANK(D$3:D$49,D4))*100 -> 10.8 | L4: =100-((PERCENTRANK(E$3:E$49,E4))*100) -> 10.9 | M4: =(PERCENTRANK(F$3:F$49,F4))*100 -> 13
A5: Rickea Jackson | B5: 20.101803 | C5: 30.223805 | D5: 0.66509835 | E5: 10.102371 | F5: 1.9898105 | I5: =(PERCENTRANK(B$3:B$49,B5))*100 -> 56.5 | J5: =(PERCENTRANK(C$3:C$49,C5))*100 -> 28.2 | K5: =(PERCENTRANK(D$3:D$49,D5))*100 -> 60.8 | L5: =100-((PERCENTRANK(E$3:E$49,E5))*100) -> 54.4 | M5: =(PERCENTRANK(F$3:F$49,F5))*100 -> 50
A6: Cameron Brink | B6: 11.436387 | C6: 32.969818 | D6: 0.34687442 | E6: 17.115961 | F6: 0.66817089 | I6: =(PERCENTRANK(B$3:B$49,B6))*100 -> 30.4 | J6: =(PERCENTRANK(C$3:C$49,C6))*100 -> 47.8 | K6: =(PERCENTRANK(D$3:D$49,D6))*100 -> 28.2 | L6: =100-((PERCENTRANK(E$3:E$49,E6))*100) -> 6.6 | M6: =(PERCENTRANK(F$3:F$49,F6))*100 -> 23.9
A7: Kate Martin | B7: 10.640765 | C7: 26.787801 | D7: 0.3972243 | E7: 13.297872 | F7: 0.80018556 | I7: =(PERCENTRANK(B$3:B$49,B7))*100 -> 26 | J7: =(PERCENTRANK(C$3:C$49,C7))*100 -> 19.5 | K7: =(PERCENTRANK(D$3:D$49,D7))*100 -> 32.6 | L7: =100-((PERCENTRANK(E$3:E$49,E7))*100) -> 17.4 | M7: =(PERCENTRANK(F$3:F$49,F7))*100 -> 26
A8: Aari McDonald | B8: 0 | C8: 31.584907 | D8: 0 | E8: 0 | F8: 0 | I8: =(PERCENTRANK(B$3:B$49,B8))*100 -> 0 | J8: =(PERCENTRANK(C$3:C$49,C8))*100 -> 41.3 | K8: =(PERCENTRANK(D$3:D$49,D8))*100 -> 0 | L8: =100-((PERCENTRANK(E$3:E$49,E8))*100) -> 100 | M8: =(PERCENTRANK(F$3:F$49,F8))*100 -> 0
A9: Brittney Sykes | B9: 16.306954 | C9: 40.648012 | D9: 0.40117471 | E9: 11.478421 | F9: 1.4206619 | I9: =(PERCENTRANK(B$3:B$49,B9))*100 -> 45.6 | J9: =(PERCENTRANK(C$3:C$49,C9))*100 -> 93.4 | K9: =(PERCENTRANK(D$3:D$49,D9))*100 -> 34.7 | L9: =100-((PERCENTRANK(E$3:E$49,E9))*100) -> 41.4 | M9: =(PERCENTRANK(F$3:F$49,F9))*100 -> 43.4
A10: Jackie Young | B10: 35.494881 | C10: 36.992165 | D10: 0.95952428 | E10: 10.933882 | F10: 3.24632 | I10: =(PERCENTRANK(B$3:B$49,B10))*100 -> 86.9 | J10: =(PERCENTRANK(C$3:C$49,C10))*100 -> 69.5 | K10: =(PERCENTRANK(D$3:D$49,D10))*100 -> 80.4 | L10: =100-((PERCENTRANK(E$3:E$49,E10))*100) -> 45.7 | M10: =(PERCENTRANK(F$3:F$49,F10))*100 -> 80.4
A11: Alyssa Thomas | B11: 29.383886 | C11: 24.624894 | D11: 1.1932594 | E11: 13.547311 | F11: 2.1689829 | I11: =(PERCENTRANK(B$3:B$49,B11))*100 -> 80.4 | J11: =(PERCENTRANK(C$3:C$49,C11))*100 -> 15.2 | K11: =(PERCENTRANK(D$3:D$49,D11))*100 -> 86.9 | L11: =100-((PERCENTRANK(E$3:E$49,E11))*100) -> 13.1 | M11: =(PERCENTRANK(F$3:F$49,F11))*100 -> 56.5
A12: Naz Hillmon | B12: 8.2568807 | C12: 27.236606 | D12: 0.30315381 | E12: 13.396538 | F12: 0.61634439 | I12: =(PERCENTRANK(B$3:B$49,B12))*100 -> 17.3 | J12: =(PERCENTRANK(C$3:C$49,C12))*100 -> 21.7 | K12: =(PERCENTRANK(D$3:D$49,D12))*100 -> 23.9 | L12: =100-((PERCENTRANK(E$3:E$49,E12))*100) -> 15.3 | M12: =(PERCENTRANK(F$3:F$49,F12))*100 -> 17.3
A13: Maddy Siegrist | B13: 5.0420168 | C13: 34.301037 | D13: 0.14699313 | E13: 9.9750623 | F13: 0.50546218 | I13: =(PERCENTRANK(B$3:B$49,B13))*100 -> 8.6 | J13: =(PERCENTRANK(C$3:C$49,C13))*100 -> 54.3 | K13: =(PERCENTRANK(D$3:D$49,D13))*100 -> 6.5 | L13: =100-((PERCENTRANK(E$3:E$49,E13))*100) -> 58.7 | M13: =(PERCENTRANK(F$3:F$49,F13))*100 -> 8.6
A14: Jordin Canada | B14: 45.401174 | C14: 36.362845 | D14: 1.2485594 | E14: 7.5037519 | F14: 6.0504631 | I14: =(PERCENTRANK(B$3:B$49,B14))*100 -> 97.8 | J14: =(PERCENTRANK(C$3:C$49,C14))*100 -> 65.2 | K14: =(PERCENTRANK(D$3:D$49,D14))*100 -> 93.4 | L14: =100-((PERCENTRANK(E$3:E$49,E14))*100) -> 76.1 | M14: =(PERCENTRANK(F$3:F$49,F14))*100 -> 100
... A51: Courtney Williams | B51: 45.392757 | C51: 32.312796 | D51: 1.404792 | E51: 14.078842 | F51: 3.2241827 | I51: =(PERCENTRANK(B$3:B$49,B51))*100 -> 97.8 | J51: =(PERCENTRANK(C$3:C$49,C51))*100 -> 46.4 | K51: =(PERCENTRANK(D$3:D$49,D51))*100 -> 98 | L51: =100-((PERCENTRANK(E$3:E$49,E51))*100) -> 12.5 | M51: =(PERCENTRANK(F$3:F$49,F51))*100 -> 79.9

Sheet BREEZE
A1: PLAYER | B1: GP | C1: MIN | D1: PTS | E1: FGM | F1: FGA | G1: 3PM | H1: 3PA | I1: FTM | J1: FTA | K1: OR | L1: DR | M1: REB | N1: AST | O1: STL | P1: BLK | Q1: TO | R1: PF | S1: AST% | T1: USG% | U1: R. PLAY | V1: TOV% | W1: AST% : TOV%
A2: Paige Bueckers | B2: 10 | C2: 206 | D2: 250 | E2: 96 | F2: 173 | G2: 15 | H2: 38 | I2: 27 | J2: 30 | K2: 5 | L2: 58 | M2: 63 | N2: 67 | O2: 9 | P2: 6 | Q2: 24 | R2: 29 | S2: =100*(N2)/((C2/($C$15/3))*$E$15-E2) -> 50.053944 | T2: =(100*(F2+0.44*J2+Q2)*($C$15/3))/(C2*($F$15+0.44*$J$15+$Q$15)) -> 36.348351 | U2: =S2/T2 -> 1.3770623 | V2: =100*Q2/(F2+0.44*J2+Q2) -> 11.417697 | W2: =IF(V2=0,0,S2/V2) -> 4.3838913
A3: Dominique Malonga | B3: 10 | C3: 146 | D3: 154 | E3: 65 | F3: 124 | G3: 4 | H3: 15 | I3: 11 | J3: 14 | K3: 24 | L3: 82 | M3: 106 | N3: 8 | O3: 4 | P3: 9 | Q3: 24 | R3: 25 | S3: =100*(N3)/((C3/($C$15/3))*$E$15-E3) -> 8.1709896 | T3: =(100*(F3+0.44*J3+Q3)*($C$15/3))/(C3*($F$15+0.44*$J$15+$Q$15)) -> 37.613008 | U3: =S3/T3 -> 0.2172384 | V3: =100*Q3/(F3+0.44*J3+Q3) -> 15.568241 | W3: =IF(V3=0,0,S3/V3) -> 0.5248499
A4: Rickea Jackson | B4: 9 | C4: 175 | D4: 140 | E4: 51 | F4: 126 | G4: 11 | H4: 33 | I4: 14 | J4: 17 | K4: 8 | L4: 51 | M4: 59 | N4: 29 | O4: 5 | P4: 3 | Q4: 15 | R4: 20 | S4: =100*(N4)/((C4/($C$15/3))*$E$15-E4) -> 20.101803 | T4: =(100*(F4+0.44*J4+Q4)*($C$15/3))/(C4*($F$15+0.44*$J$15+$Q$15)) -> 30.223805 | U4: =S4/T4 -> 0.66509835 | V4: =100*Q4/(F4+0.44*J4+Q4) -> 10.102371 | W4: =IF(V4=0,0,S4/V4) -> 1.9898105
A5: Cameron Brink | B5: 9 | C5: 101 | D5: 97 | E5: 34 | F5: 70 | G5: 5 | H5: 19 | I5: 12 | J5: 17 | K5: 13 | L5: 40 | M5: 53 | N5: 9 | O5: 1 | P5: 14 | Q5: 16 | R5: 31 | S5: =100*(N5)/((C5/($C$15/3))*$E$15-E5) -> 11.436387 | T5: =(100*(F5+0.44*J5+Q5)*($C$15/3))/(C5*($F$15+0.44*$J$15+$Q$15)) -> 32.969818 | U5: =S5/T5 -> 0.34687442 | V5: =100*Q5/(F5+0.44*J5+Q5) -> 17.115961 | W5: =IF(V5=0,0,S5/V5) -> 0.66817089
A6: Kate Martin | B6: 10 | C6: 100 | D6: 66 | E6: 27 | F6: 63 | G6: 5 | H6: 28 | I6: 3 | J6: 5 | K6: 7 | L6: 29 | M6: 36 | N6: 9 | O6: 2 | P6: 2 | Q6: 10 | R6: 20 | S6: =100*(N6)/((C6/($C$15/3))*$E$15-E6) -> 10.640765 | T6: =(100*(F6+0.44*J6+Q6)*($C$15/3))/(C6*($F$15+0.44*$J$15+$Q$15)) -> 26.787801 | U6: =S6/T6 -> 0.3972243 | V6: =100*Q6/(F6+0.44*J6+Q6) -> 13.297872 | W6: =IF(V6=0,0,S6/V6) -> 0.80018556
A7: Aari McDonald | B7: 1 | C7: 6 | D7: 2 | E7: 0 | F7: 4 | G7: 0 | H7: 1 | I7: 1 | J7: 3 | K7: 1 | L7: 0 | M7: 1 | N7: 0 | O7: 0 | P7: 0 | Q7: 0 | R7: 2 | S7: =100*(N7)/((C7/($C$15/3))*$E$15-E7) -> 0 | T7: =(100*(F7+0.44*J7+Q7)*($C$15/3))/(C7*($F$15+0.44*$J$15+$Q$15)) -> 31.584907 | U7: =S7/T7 -> 0 | V7: =100*Q7/(F7+0.44*J7+Q7) -> 0 | W7: =IF(V7=0,0,S7/V7) -> 0
S8: =100*(N8)/((C8/($C$15/3))*$E$15-E8) -> #DIV/0! | T8: =(100*(F8+0.44*J8+Q8)*($C$15/3))/(C8*($F$15+0.44*$J$15+$Q$15)) -> #DIV/0! | U8: =S8/T8 -> #DIV/0! | V8: =100*Q8/(F8+0.44*J8+Q8) -> #DIV/0! | W8: =IF(V8=0,0,S8/V8) -> #DIV/0!
S9: =100*(N9)/((C9/($C$15/3))*$E$15-E9) -> #DIV/0! | T9: =(100*(F9+0.44*J9+Q9)*($C$15/3))/(C9*($F$15+0.44*$J$15+$Q$15)) -> #DIV/0! | U9: =S9/T9 -> #DIV/0! | V9: =100*Q9/(F9+0.44*J9+Q9) -> #DIV/0! | W9: =IF(V9=0,0,S9/V9) -> #DIV/0!
S10: =100*(N10)/((C10/($C$15/3))*$E$15-E10) -> #DIV/0! | T10: =(100*(F10+0.44*J10+Q10)*($C$15/3))/(C10*($F$15+0.44*$J$15+$Q$15)) -> #DIV/0! | U10: =S10/T10 -> #DIV/0! | V10: =100*Q10/(F10+0.44*J10+Q10) -> #DIV/0! | W10: =IF(V10=0,0,S10/V10) -> #DIV/0!
S11: =100*(N11)/((C11/($C$15/3))*$E$15-E11) -> #DIV/0! | T11: =(100*(F11+0.44*J11+Q11)*($C$15/3))/(C11*($F$15+0.44*$J$15+$Q$15)) -> #DIV/0! | U11: =S11/T11 -> #DIV/0! | V11: =100*Q11/(F11+0.44*J11+Q11) -> #DIV/0! | W11: =IF(V11=0,0,S11/V11) -> #DIV/0!
S12: =100*(N12)/((C12/($C$15/3))*$E$15-E12) -> #DIV/0! | T12: =(100*(F12+0.44*J12+Q12)*($C$15/3))/(C12*($F$15+0.44*$J$15+$Q$15)) -> #DIV/0! | U12: =S12/T12 -> #DIV/0! | V12: =100*Q12/(F12+0.44*J12+Q12) -> #DIV/0! | W12: =IF(V12=0,0,S12/V12) -> #DIV/0!
S13: =100*(N13)/((C13/($C$15/3))*$E$15-E13) -> #DIV/0! | T13: =(100*(F13+0.44*J13+Q13)*($C$15/3))/(C13*($F$15+0.44*$J$15+$Q$15)) -> #DIV/0! | U13: =S13/T13 -> #DIV/0! | V13: =100*Q13/(F13+0.44*J13+Q13) -> #DIV/0! | W13: =IF(V13=0,0,S13/V13) -> #DIV/0!
A15: SOMME | B15: =SUM(B2:B13) -> 49 | C15: =SUM(C2:C13) -> 734 | D15: =SUM(D2:D13) -> 709 | E15: =SUM(E2:E13) -> 273 | F15: =SUM(F2:F13) -> 560 | G15: =SUM(G2:G13) -> 40 | H15: =SUM(H2:H13) -> 134 | I15: =SUM(I2:I13) -> 68 | ... R15: =SUM(R2:R13) -> 127

Sheet LACES
A1: PLAYER | B1: GP | C1: MIN | D1: PTS | E1: FGM | F1: FGA | G1: 3PM | H1: 3PA | I1: FTM | J1: FTA | K1: OR | L1: DR | M1: REB | N1: AST | O1: STL | P1: BLK | Q1: TO | R1: PF | S1: AST% | T1: USG% | U1: R. PLAY | V1: TOV% | W1: AST% : TOV%
A2: Brittney Sykes | B2: 10 | C2: 154 | D2: 189 | E2: 69 | F2: 145 | G2: 22 | H2: 52 | I2: 16 | J2: 21 | K2: 4 | L2: 34 | M2: 38 | N2: 17 | O2: 16 | P2: 3 | Q2: 20 | R2: 32 | S2: =100*(N2)/((C2/($C$15/3))*$E$15-E2) -> 16.306954 | T2: =(100*(F2+0.44*J2+Q2)*($C$15/3))/(C2*($F$15+0.44*$J$15+$Q$15)) -> 40.648012 | U2: =S2/T2 -> 0.40117471 | V2: =100*Q2/(F2+0.44*J2+Q2) -> 11.478421 | W2: =IF(V2=0,0,S2/V2) -> 1.4206619
A3: Jackie Young | B3: 10 | C3: 151 | D3: 164 | E3: 60 | F3: 131 | G3: 17 | H3: 50 | I3: 16 | J3: 17 | K3: 9 | L3: 29 | M3: 38 | N3: 39 | O3: 8 | P3: 2 | Q3: 17 | R3: 21 | S3: =100*(N3)/((C3/($C$15/3))*$E$15-E3) -> 35.494881 | T3: =(100*(F3+0.44*J3+Q3)*($C$15/3))/(C3*($F$15+0.44*$J$15+$Q$15)) -> 36.992165 | U3: =S3/T3 -> 0.95952428 | V3: =100*Q3/(F3+0.44*J3+Q3) -> 10.933882 | W3: =IF(V3=0,0,S3/V3) -> 3.24632
A4: Alyssa Thomas | B4: 10 | C4: 140 | D4: 116 | E4: 52 | F4: 79 | G4: 0 | H4: 0 | I4: 7 | J4: 9 | K4: 10 | L4: 66 | M4: 76 | N4: 31 | O4: 8 | P4: 3 | Q4: 13 | R4: 16 | S4: =100*(N4)/((C4/($C$15/3))*$E$15-E4) -> 29.383886 | T4: =(100*(F4+0.44*J4+Q4)*($C$15/3))/(C4*($F$15+0.44*$J$15+$Q$15)) -> 24.624894 | U4: =S4/T4 -> 1.1932594 | V4: =100*Q4/(F4+0.44*J4+Q4) -> 13.547311 | W4: =IF(V4=0,0,S4/V4) -> 2.1689829
A5: Naz Hillmon | B5: 10 | C5: 128 | D5: 97 | E5: 35 | F5: 77 | G5: 10 | H5: 40 | I5: 9 | J5: 16 | K5: 18 | L5: 52 | M5: 70 | N5: 9 | O5: 7 | P5: 4 | Q5: 13 | R5: 17 | S5: =100*(N5)/((C5/($C$15/3))*$E$15-E5) -> 8.2568807 | T5: =(100*(F5+0.44*J5+Q5)*($C$15/3))/(C5*($F$15+0.44*$J$15+$Q$15)) -> 27.236606 | U5: =S5/T5 -> 0.30315381 | V5: =100*Q5/(F5+0.44*J5+Q5) -> 13.396538 | W5: =IF(V5=0,0,S5/V5) -> 0.61634439
A6: Maddy Siegrist | B6: 9 | C6: 84 | D6: 84 | E6: 35 | F6: 70 | G6: 8 | H6: 24 | I6: 3 | J6: 5 | K6: 8 | L6: 24 | M6: 32 | N6: 3 | O6: 4 | P6: 0 | Q6: 8 | R6: 18 | S6: =100*(N6)/((C6/($C$15/3))*$E$15-E6) -> 5.0420168 | T6: =(100*(F6+0.44*J6+Q6)*($C$15/3))/(C6*($F$15+0.44*$J$15+$Q$15)) -> 34.301037 | U6: =S6/T6 -> 0.14699313 | V6: =100*Q6/(F6+0.44*J6+Q6) -> 9.9750623 | W6: =IF(V6=0,0,S6/V6) -> 0.50546218
A7: Jordin Canada | B7: 8 | C7: 79 | D7: 69 | E7: 25 | F7: 70 | G7: 6 | H7: 23 | I7: 7 | J7: 9 | K7: 3 | L7: 33 | M7: 36 | N7: 29 | O7: 7 | P7: 2 | Q7: 6 | R7: 20 | S7: =100*(N7)/((C7/($C$15/3))*$E$15-E7) -> 45.401174 | T7: =(100*(F7+0.44*J7+Q7)*($C$15/3))/(C7*($F$15+0.44*$J$15+$Q$15)) -> 36.362845 | U7: =S7/T7 -> 1.2485594 | V7: =100*Q7/(F7+0.44*J7+Q7) -> 7.5037519 | W7: =IF(V7=0,0,S7/V7) -> 6.0504631
S8: =100*(N8)/((C8/($C$15/3))*$E$15-E8) -> #DIV/0! | T8: =(100*(F8+0.44*J8+Q8)*($C$15/3))/(C8*($F$15+0.44*$J$15+$Q$15)) -> #DIV/0! | U8: =S8/T8 -> #DIV/0! | V8: =100*Q8/(F8+0.44*J8+Q8) -> #DIV/0! | W8: =IF(V8=0,0,S8/V8) -> #DIV/0!
S9: =100*(N9)/((C9/($C$15/3))*$E$15-E9) -> #DIV/0! | T9: =(100*(F9+0.44*J9+Q9)*($C$15/3))/(C9*($F$15+0.44*$J$15+$Q$15)) -> #DIV/0! | U9: =S9/T9 -> #DIV/0! | V9: =100*Q9/(F9+0.44*J9+Q9) -> #DIV/0! | W9: =IF(V9=0,0,S9/V9) -> #DIV/0!
S10: =100*(N10)/((C10/($C$15/3))*$E$15-E10) -> #DIV/0! | T10: =(100*(F10+0.44*J10+Q10)*($C$15/3))/(C10*($F$15+0.44*$J$15+$Q$15)) -> #DIV/0! | U10: =S10/T10 -> #DIV/0! | V10: =100*Q10/(F10+0.44*J10+Q10) -> #DIV/0! | W10: =IF(V10=0,0,S10/V10) -> #DIV/0!
S11: =100*(N11)/((C11/($C$15/3))*$E$15-E11) -> #DIV/0! | T11: =(100*(F11+0.44*J11+Q11)*($C$15/3))/(C11*($F$15+0.44*$J$15+$Q$15)) -> #DIV/0! | U11: =S11/T11 -> #DIV/0! | V11: =100*Q11/(F11+0.44*J11+Q11) -> #DIV/0! | W11: =IF(V11=0,0,S11/V11) -> #DIV/0!
S12: =100*(N12)/((C12/($C$15/3))*$E$15-E12) -> #DIV/0! | T12: =(100*(F12+0.44*J12+Q12)*($C$15/3))/(C12*($F$15+0.44*$J$15+$Q$15)) -> #DIV/0! | U12: =S12/T12 -> #DIV/0! | V12: =100*Q12/(F12+0.44*J12+Q12) -> #DIV/0! | W12: =IF(V12=0,0,S12/V12) -> #DIV/0!
S13: =100*(N13)/((C13/($C$15/3))*$E$15-E13) -> #DIV/0! | T13: =(100*(F13+0.44*J13+Q13)*($C$15/3))/(C13*($F$15+0.44*$J$15+$Q$15)) -> #DIV/0! | U13: =S13/T13 -> #DIV/0! | V13: =100*Q13/(F13+0.44*J13+Q13) -> #DIV/0! | W13: =IF(V13=0,0,S13/V13) -> #DIV/0!
A15: SOMME | B15: =SUM(B2:B13) -> 57 | C15: =SUM(C2:C13) -> 736 | D15: =SUM(D2:D13) -> 719 | E15: =SUM(E2:E13) -> 276 | F15: =SUM(F2:F13) -> 572 | G15: =SUM(G2:G13) -> 63 | H15: =SUM(H2:H13) -> 189 | I15: =SUM(I2:I13) -> 58 | ... R15: =SUM(R2:R13) -> 124

Sheet MIST
A1: PLAYER | B1: GP | C1: MIN | D1: PTS | E1: FGM | F1: FGA | G1: 3PM | H1: 3PA | I1: FTM | J1: FTA | K1: OR | L1: DR | M1: REB | N1: AST | O1: STL | P1: BLK | Q1: TO | R1: PF | S1: AST% | T1: USG% | U1: R. PLAY | V1: TOV% | W1: AST% : TOV%
A2: Breanna Stewart | B2: 10 | C2: 168 | D2: 201 | E2: 76 | F2: 157 | G2: 9 | H2: 37 | I2: 23 | J2: 27 | K2: 15 | L2: 77 | M2: 92 | N2: 26 | O2: 11 | P2: 6 | Q2: 18 | R2: 19 | S2: =100*(N2)/((C2/($C$15/3))*$E$15-E2) -> 23.758621 | T2: =(100*(F2+0.44*J2+Q2)*($C$15/3))/(C2*($F$15+0.44*$J$15+$Q$15)) -> 38.216592 | U2: =S2/T2 -> 0.6216834 | V2: =100*Q2/(F2+0.44*J2+Q2) -> 9.6318493 | W2: =IF(V2=0,0,S2/V2) -> 2.4666728
A3: Allisha Gray | B3: 10 | C3: 158 | D3: 201 | E3: 68 | F3: 158 | G3: 22 | H3: 67 | I3: 22 | J3: 26 | K3: 9 | L3: 34 | M3: 43 | N3: 30 | O3: 9 | P3: 8 | Q3: 16 | R3: 18 | S3: =100*(N3)/((C3/($C$15/3))*$E$15-E3) -> 28.196489 | T3: =(100*(F3+0.44*J3+Q3)*($C$15/3))/(C3*($F$15+0.44*$J$15+$Q$15)) -> 40.322249 | U3: =S3/T3 -> 0.69927868 | V3: =100*Q3/(F3+0.44*J3+Q3) -> 8.6281277 | W3: =IF(V3=0,0,S3/V3) -> 3.267973
A4: Arike Ogunbowale | B4: 10 | C4: 128 | D4: 130 | E4: 49 | F4: 119 | G4: 17 | H4: 48 | I4: 8 | J4: 11 | K4: 8 | L4: 21 | M4: 29 | N4: 21 | O4: 13 | P4: 1 | Q4: 15 | R4: 21 | S4: =100*(N4)/((C4/($C$15/3))*$E$15-E4) -> 22.756083 | T4: =(100*(F4+0.44*J4+Q4)*($C$15/3))/(C4*($F$15+0.44*$J$15+$Q$15)) -> 37.265165 | U4: =S4/T4 -> 0.61065294 | V4: =100*Q4/(F4+0.44*J4+Q4) -> 10.803803 | W4: =IF(V4=0,0,S4/V4) -> 2.106303
A5: Veronica Burton | B5: 10 | C5: 148 | D5: 91 | E5: 32 | F5: 83 | G5: 8 | H5: 33 | I5: 11 | J5: 15 | K5: 16 | L5: 33 | M5: 49 | N5: 35 | O5: 18 | P5: 5 | Q5: 6 | R5: 24 | S5: =100*(N5)/((C5/($C$15/3))*$E$15-E5) -> 26.644642 | T5: =(100*(F5+0.44*J5+Q5)*($C$15/3))/(C5*($F$15+0.44*$J$15+$Q$15)) -> 22.191905 | U5: =S5/T5 -> 1.2006469 | V5: =100*Q5/(F5+0.44*J5+Q5) -> 6.2761506 | W5: =IF(V5=0,0,S5/V5) -> 4.2453797
A6: Alanna Smith | B6: 10 | C6: 85 | D6: 71 | E6: 31 | F6: 59 | G6: 2 | H6: 14 | I6: 4 | J6: 9 | K6: 12 | L6: 38 | M6: 50 | N6: 5 | O6: 4 | P6: 7 | Q6: 9 | R6: 24 | S6: =100*(N6)/((C6/($C$15/3))*$E$15-E6) -> 7.959153 | T6: =(100*(F6+0.44*J6+Q6)*($C$15/3))/(C6*($F$15+0.44*$J$15+$Q$15)) -> 29.085105 | U6: =S6/T6 -> 0.27365048 | V6: =100*Q6/(F6+0.44*J6+Q6) -> 12.506948 | W6: =IF(V6=0,0,S6/V6) -> 0.6363785
A7: Li Yueru | B7: 10 | C7: 55 | D7: 45 | E7: 17 | F7: 36 | G7: 2 | H7: 11 | I7: 5 | J7: 5 | K7: 9 | L7: 21 | M7: 30 | N7: 2 | O7: 2 | P7: 2 | Q7: 3 | R7: 13 | S7: =100*(N7)/((C7/($C$15/3))*$E$15-E7) -> 4.5758688 | T7: =(100*(F7+0.44*J7+Q7)*($C$15/3))/(C7*($F$15+0.44*$J$15+$Q$15)) -> 25.735519 | U7: =S7/T7 -> 0.17780363 | V7: =100*Q7/(F7+0.44*J7+Q7) -> 7.2815534 | W7: =IF(V7=0,0,S7/V7) -> 0.62841931
S8: =100*(N8)/((C8/($C$15/3))*$E$15-E8) -> #DIV/0! | T8: =(100*(F8+0.44*J8+Q8)*($C$15/3))/(C8*($F$15+0.44*$J$15+$Q$15)) -> #DIV/0! | U8: =S8/T8 -> #DIV/0! | V8: =100*Q8/(F8+0.44*J8+Q8) -> #DIV/0! | W8: =IF(V8=0,0,S8/V8) -> #DIV/0!
S9: =100*(N9)/((C9/($C$15/3))*$E$15-E9) -> #DIV/0! | T9: =(100*(F9+0.44*J9+Q9)*($C$15/3))/(C9*($F$15+0.44*$J$15+$Q$15)) -> #DIV/0! | U9: =S9/T9 -> #DIV/0! | V9: =100*Q9/(F9+0.44*J9+Q9) -> #DIV/0! | W9: =IF(V9=0,0,S9/V9) -> #DIV/0!
S10: =100*(N10)/((C10/($C$15/3))*$E$15-E10) -> #DIV/0! | T10: =(100*(F10+0.44*J10+Q10)*($C$15/3))/(C10*($F$15+0.44*$J$15+$Q$15)) -> #DIV/0! | U10: =S10/T10 -> #DIV/0! | V10: =100*Q10/(F10+0.44*J10+Q10) -> #DIV/0! | W10: =IF(V10=0,0,S10/V10) -> #DIV/0!
S11: =100*(N11)/((C11/($C$15/3))*$E$15-E11) -> #DIV/0! | T11: =(100*(F11+0.44*J11+Q11)*($C$15/3))/(C11*($F$15+0.44*$J$15+$Q$15)) -> #DIV/0! | U11: =S11/T11 -> #DIV/0! | V11: =100*Q11/(F11+0.44*J11+Q11) -> #DIV/0! | W11: =IF(V11=0,0,S11/V11) -> #DIV/0!
S12: =100*(N12)/((C12/($C$15/3))*$E$15-E12) -> #DIV/0! | T12: =(100*(F12+0.44*J12+Q12)*($C$15/3))/(C12*($F$15+0.44*$J$15+$Q$15)) -> #DIV/0! | U12: =S12/T12 -> #DIV/0! | V12: =100*Q12/(F12+0.44*J12+Q12) -> #DIV/0! | W12: =IF(V12=0,0,S12/V12) -> #DIV/0!
S13: =100*(N13)/((C13/($C$15/3))*$E$15-E13) -> #DIV/0! | T13: =(100*(F13+0.44*J13+Q13)*($C$15/3))/(C13*($F$15+0.44*$J$15+$Q$15)) -> #DIV/0! | U13: =S13/T13 -> #DIV/0! | V13: =100*Q13/(F13+0.44*J13+Q13) -> #DIV/0! | W13: =IF(V13=0,0,S13/V13) -> #DIV/0!
A15: SOMME | B15: =SUM(B2:B13) -> 60 | C15: =SUM(C2:C13) -> 742 | D15: =SUM(D2:D13) -> 739 | E15: =SUM(E2:E13) -> 273 | F15: =SUM(F2:F13) -> 612 | G15: =SUM(G2:G13) -> 60 | H15: =SUM(H2:H13) -> 210 | I15: =SUM(I2:I13) -> 73 | ... R15: =SUM(R2:R13) -> 119

Sheet ROSE
A1: PLAYER | B1: GP | C1: MIN | D1: PTS | E1: FGM | F1: FGA | G1: 3PM | H1: 3PA | I1: FTM | J1: FTA | K1: OR | L1: DR | M1: REB | N1: AST | O1: STL | P1: BLK | Q1: TO | R1: PF | S1: AST% | T1: USG% | U1: R. PLAY | V1: TOV% | W1: AST% : TOV%
A2: Chelsea Gray | B2: 10 | C2: 225 | D2: 259 | E2: 91 | F2: 178 | G2: 34 | H2: 73 | I2: 21 | J2: 22 | K2: 7 | L2: 50 | M2: 57 | N2: 68 | O2: 16 | P2: 5 | Q2: 23 | R2: 23 | S2: =100*(N2)/((C2/($C$15/3))*$E$15-E2) -> 44.235953 | T2: =(100*(F2+0.44*J2+Q2)*($C$15/3))/(C2*($F$15+0.44*$J$15+$Q$15)) -> 35.055373 | U2: =S2/T2 -> 1.2618879 | V2: =100*Q2/(F2+0.44*J2+Q2) -> 10.917031 | W2: =IF(V2=0,0,S2/V2) -> 4.0520133
A3: Shakira Austin | B3: 10 | C3: 159 | D3: 162 | E3: 64 | F3: 113 | G3: 0 | H3: 5 | I3: 20 | J3: 31 | K3: 14 | L3: 71 | M3: 85 | N3: 12 | O3: 3 | P3: 10 | Q3: 18 | R3: 26 | S3: =100*(N3)/((C3/($C$15/3))*$E$15-E3) -> 11.015616 | T3: =(100*(F3+0.44*J3+Q3)*($C$15/3))/(C3*($F$15+0.44*$J$15+$Q$15)) -> 34.056898 | U3: =S3/T3 -> 0.32344744 | V3: =100*Q3/(F3+0.44*J3+Q3) -> 12.44469 | W3: =IF(V3=0,0,S3/V3) -> 0.88516598
A4: Kahleah Copper | B4: 7 | C4: 126 | D4: 142 | E4: 55 | F4: 114 | G4: 16 | H4: 40 | I4: 9 | J4: 12 | K4: 7 | L4: 25 | M4: 32 | N4: 4 | O4: 1 | P4: 2 | Q4: 4 | R4: 25 | S4: =100*(N4)/((C4/($C$15/3))*$E$15-E4) -> 4.8754431 | T4: =(100*(F4+0.44*J4+Q4)*($C$15/3))/(C4*($F$15+0.44*$J$15+$Q$15)) -> 36.629913 | U4: =S4/T4 -> 0.13310005 | V4: =100*Q4/(F4+0.44*J4+Q4) -> 3.2446463 | W4: =IF(V4=0,0,S4/V4) -> 1.5026116
A5: Azurá Stevens | B5: 8 | C5: 84 | D5: 79 | E5: 30 | F5: 77 | G5: 7 | H5: 26 | I5: 7 | J5: 7 | K5: 14 | L5: 36 | M5: 50 | N5: 12 | O5: 2 | P5: 3 | Q5: 5 | R5: 12 | S5: =100*(N5)/((C5/($C$15/3))*$E$15-E5) -> 19.555902 | T5: =(100*(F5+0.44*J5+Q5)*($C$15/3))/(C5*($F$15+0.44*$J$15+$Q$15)) -> 37.919447 | U5: =S5/T5 -> 0.51572223 | V5: =100*Q5/(F5+0.44*J5+Q5) -> 5.8768218 | W5: =IF(V5=0,0,S5/V5) -> 3.3276323
A6: Sug Sutton | B6: 8 | C6: 58 | D6: 42 | E6: 17 | F6: 41 | G6: 6 | H6: 23 | I6: 1 | J6: 1 | K6: 1 | L6: 7 | M6: 8 | N6: 12 | O6: 6 | P6: 0 | Q6: 2 | R6: 18 | S6: =100*(N6)/((C6/($C$15/3))*$E$15-E6) -> 26.039595 | T6: =(100*(F6+0.44*J6+Q6)*($C$15/3))/(C6*($F$15+0.44*$J$15+$Q$15)) -> 28.039846 | U6: =S6/T6 -> 0.92866399 | V6: =100*Q6/(F6+0.44*J6+Q6) -> 4.6040516 | W6: =IF(V6=0,0,S6/V6) -> 5.6558001
A7: Lexie Hull | B7: 9 | C7: 91 | D7: 37 | E7: 13 | F7: 46 | G7: 5 | H7: 22 | I7: 3 | J7: 3 | K7: 11 | L7: 18 | M7: 29 | N7: 5 | O7: 11 | P7: 2 | Q7: 10 | R7: 18 | S7: =100*(N7)/((C7/($C$15/3))*$E$15-E7) -> 5.81557 | T7: =(100*(F7+0.44*J7+Q7)*($C$15/3))/(C7*($F$15+0.44*$J$15+$Q$15)) -> 23.581889 | U7: =S7/T7 -> 0.24661171 | V7: =100*Q7/(F7+0.44*J7+Q7) -> 17.445918 | W7: =IF(V7=0,0,S7/V7) -> 0.33334847
A8: Haley Jones | B8: 2 | C8: 10 | D8: 6 | E8: 3 | F8: 6 | G8: 0 | H8: 0 | I8: 0 | J8: 0 | K8: 1 | L8: 2 | M8: 3 | N8: 3 | O8: 0 | P8: 1 | Q8: 0 | R8: 2 | S8: =100*(N8)/((C8/($C$15/3))*$E$15-E8) -> 38.088012 | T8: =(100*(F8+0.44*J8+Q8)*($C$15/3))/(C8*($F$15+0.44*$J$15+$Q$15)) -> 22.46286 | U8: =S8/T8 -> 1.6955994 | V8: =100*Q8/(F8+0.44*J8+Q8) -> 0 | W8: =IF(V8=0,0,S8/V8) -> 0
S9: =100*(N9)/((C9/($C$15/3))*$E$15-E9) -> #DIV/0! | T9: =(100*(F9+0.44*J9+Q9)*($C$15/3))/(C9*($F$15+0.44*$J$15+$Q$15)) -> #DIV/0! | U9: =S9/T9 -> #DIV/0! | V9: =100*Q9/(F9+0.44*J9+Q9) -> #DIV/0! | W9: =IF(V9=0,0,S9/V9) -> #DIV/0!
S10: =100*(N10)/((C10/($C$15/3))*$E$15-E10) -> #DIV/0! | T10: =(100*(F10+0.44*J10+Q10)*($C$15/3))/(C10*($F$15+0.44*$J$15+$Q$15)) -> #DIV/0! | U10: =S10/T10 -> #DIV/0! | V10: =100*Q10/(F10+0.44*J10+Q10) -> #DIV/0! | W10: =IF(V10=0,0,S10/V10) -> #DIV/0!
S11: =100*(N11)/((C11/($C$15/3))*$E$15-E11) -> #DIV/0! | T11: =(100*(F11+0.44*J11+Q11)*($C$15/3))/(C11*($F$15+0.44*$J$15+$Q$15)) -> #DIV/0! | U11: =S11/T11 -> #DIV/0! | V11: =100*Q11/(F11+0.44*J11+Q11) -> #DIV/0! | W11: =IF(V11=0,0,S11/V11) -> #DIV/0!
S12: =100*(N12)/((C12/($C$15/3))*$E$15-E12) -> #DIV/0! | T12: =(100*(F12+0.44*J12+Q12)*($C$15/3))/(C12*($F$15+0.44*$J$15+$Q$15)) -> #DIV/0! | U12: =S12/T12 -> #DIV/0! | V12: =100*Q12/(F12+0.44*J12+Q12) -> #DIV/0! | W12: =IF(V12=0,0,S12/V12) -> #DIV/0!
S13: =100*(N13)/((C13/($C$15/3))*$E$15-E13) -> #DIV/0! | T13: =(100*(F13+0.44*J13+Q13)*($C$15/3))/(C13*($F$15+0.44*$J$15+$Q$15)) -> #DIV/0! | U13: =S13/T13 -> #DIV/0! | V13: =100*Q13/(F13+0.44*J13+Q13) -> #DIV/0! | W13: =IF(V13=0,0,S13/V13) -> #DIV/0!
A15: SOMME | B15: =SUM(B2:B13) -> 54 | C15: =SUM(C2:C13) -> 753 | D15: =SUM(D2:D13) -> 727 | E15: =SUM(E2:E13) -> 273 | F15: =SUM(F2:F13) -> 575 | G15: =SUM(G2:G13) -> 68 | H15: =SUM(H2:H13) -> 189 | I15: =SUM(I2:I13) -> 61 | ... R15: =SUM(R2:R13) -> 124

Sheet HIVE
A1: PLAYER | B1: GP | C1: MIN | D1: PTS | E1: FGM | F1: FGA | G1: 3PM | H1: 3PA | I1: FTM | J1: FTA | K1: OR | L1: DR | M1: REB | N1: AST | O1: STL | P1: BLK | Q1: TO | R1: PF | S1: AST% | T1: USG% | U1: R. PLAY | V1: TOV% | W1: AST% : TOV%
A2: Kelsey Mitchell | B2: 10 | C2: 179 | D2: 174 | E2: 74 | F2: 143 | G2: 18 | H2: 48 | I2: 5 | J2: 9 | K2: 6 | L2: 24 | M2: 30 | N2: 21 | O2: 10 | P2: 2 | Q2: 10 | R2: 25 | S2: =100*(N2)/((C2/($C$15/3))*$E$15-E2) -> 17.459191 | T2: =(100*(F2+0.44*J2+Q2)*($C$15/3))/(C2*($F$15+0.44*$J$15+$Q$15)) -> 31.645794 | U2: =S2/T2 -> 0.55170652 | V2: =100*Q2/(F2+0.44*J2+Q2) -> 6.3710499 | W2: =IF(V2=0,0,S2/V2) -> 2.7403946
A3: Sonia Citron | B3: 10 | C3: 173 | D3: 166 | E3: 66 | F3: 139 | G3: 11 | H3: 47 | I3: 12 | J3: 14 | K3: 3 | L3: 40 | M3: 43 | N3: 30 | O3: 8 | P3: 12 | Q3: 13 | R3: 30 | S3: =100*(N3)/((C3/($C$15/3))*$E$15-E3) -> 24.636955 | T3: =(100*(F3+0.44*J3+Q3)*($C$15/3))/(C3*($F$15+0.44*$J$15+$Q$15)) -> 32.993667 | U3: =S3/T3 -> 0.7467177 | V3: =100*Q3/(F3+0.44*J3+Q3) -> 8.2195245 | W3: =IF(V3=0,0,S3/V3) -> 2.9973699
A4: Monique Billings | B4: 10 | C4: 139 | D4: 145 | E4: 55 | F4: 119 | G4: 4 | H4: 15 | I4: 17 | J4: 20 | K4: 23 | L4: 86 | M4: 109 | N4: 11 | O4: 9 | P4: 5 | Q4: 18 | R4: 25 | S4: =100*(N4)/((C4/($C$15/3))*$E$15-E4) -> 11.474367 | T4: =(100*(F4+0.44*J4+Q4)*($C$15/3))/(C4*($F$15+0.44*$J$15+$Q$15)) -> 37.854958 | U4: =S4/T4 -> 0.30311399 | V4: =100*Q4/(F4+0.44*J4+Q4) -> 12.345679 | W4: =IF(V4=0,0,S4/V4) -> 0.92942374
A5: Ezi Magbegor | B5: 7 | C5: 81 | D5: 64 | E5: 30 | F5: 59 | G5: 1 | H5: 10 | I5: 2 | J5: 3 | K5: 5 | L5: 39 | M5: 44 | N5: 8 | O5: 4 | P5: 7 | Q5: 8 | R5: 22 | S5: =100*(N5)/((C5/($C$15/3))*$E$15-E5) -> 13.813434 | T5: =(100*(F5+0.44*J5+Q5)*($C$15/3))/(C5*($F$15+0.44*$J$15+$Q$15)) -> 30.439876 | U5: =S5/T5 -> 0.45379404 | V5: =100*Q5/(F5+0.44*J5+Q5) -> 11.709602 | W5: =IF(V5=0,0,S5/V5) -> 1.1796673
A6: Natisha Hiedeman | B6: 10 | C6: 80 | D6: 56 | E6: 21 | F6: 61 | G6: 10 | H6: 28 | I6: 2 | J6: 4 | K6: 3 | L6: 15 | M6: 18 | N6: 13 | O6: 2 | P6: 1 | Q6: 6 | R6: 20 | S6: =100*(N6)/((C6/($C$15/3))*$E$15-E6) -> 19.748055 | T6: =(100*(F6+0.44*J6+Q6)*($C$15/3))/(C6*($F$15+0.44*$J$15+$Q$15)) -> 31.018866 | U6: =S6/T6 -> 0.63664657 | V6: =100*Q6/(F6+0.44*J6+Q6) -> 8.7260035 | W6: =IF(V6=0,0,S6/V6) -> 2.2631271
A7: Saniya Rivers | B7: 9 | C7: 86 | D7: 52 | E7: 21 | F7: 70 | G7: 3 | H7: 19 | I7: 4 | J7: 6 | K7: 4 | L7: 22 | M7: 26 | N7: 11 | O7: 10 | P7: 11 | Q7: 11 | R7: 16 | S7: =100*(N7)/((C7/($C$15/3))*$E$15-E7) -> 15.205664 | T7: =(100*(F7+0.44*J7+Q7)*($C$15/3))/(C7*($F$15+0.44*$J$15+$Q$15)) -> 35.09907 | U7: =S7/T7 -> 0.43322128 | V7: =100*Q7/(F7+0.44*J7+Q7) -> 13.151602 | W7: =IF(V7=0,0,S7/V7) -> 1.1561834
S8: =100*(N8)/((C8/($C$15/3))*$E$15-E8) -> #DIV/0! | T8: =(100*(F8+0.44*J8+Q8)*($C$15/3))/(C8*($F$15+0.44*$J$15+$Q$15)) -> #DIV/0! | U8: =S8/T8 -> #DIV/0! | V8: =100*Q8/(F8+0.44*J8+Q8) -> #DIV/0! | W8: =IF(V8=0,0,S8/V8) -> #DIV/0!
S9: =100*(N9)/((C9/($C$15/3))*$E$15-E9) -> #DIV/0! | T9: =(100*(F9+0.44*J9+Q9)*($C$15/3))/(C9*($F$15+0.44*$J$15+$Q$15)) -> #DIV/0! | U9: =S9/T9 -> #DIV/0! | V9: =100*Q9/(F9+0.44*J9+Q9) -> #DIV/0! | W9: =IF(V9=0,0,S9/V9) -> #DIV/0!
S10: =100*(N10)/((C10/($C$15/3))*$E$15-E10) -> #DIV/0! | T10: =(100*(F10+0.44*J10+Q10)*($C$15/3))/(C10*($F$15+0.44*$J$15+$Q$15)) -> #DIV/0! | U10: =S10/T10 -> #DIV/0! | V10: =100*Q10/(F10+0.44*J10+Q10) -> #DIV/0! | W10: =IF(V10=0,0,S10/V10) -> #DIV/0!
S11: =100*(N11)/((C11/($C$15/3))*$E$15-E11) -> #DIV/0! | T11: =(100*(F11+0.44*J11+Q11)*($C$15/3))/(C11*($F$15+0.44*$J$15+$Q$15)) -> #DIV/0! | U11: =S11/T11 -> #DIV/0! | V11: =100*Q11/(F11+0.44*J11+Q11) -> #DIV/0! | W11: =IF(V11=0,0,S11/V11) -> #DIV/0!
S12: =100*(N12)/((C12/($C$15/3))*$E$15-E12) -> #DIV/0! | T12: =(100*(F12+0.44*J12+Q12)*($C$15/3))/(C12*($F$15+0.44*$J$15+$Q$15)) -> #DIV/0! | U12: =S12/T12 -> #DIV/0! | V12: =100*Q12/(F12+0.44*J12+Q12) -> #DIV/0! | W12: =IF(V12=0,0,S12/V12) -> #DIV/0!
S13: =100*(N13)/((C13/($C$15/3))*$E$15-E13) -> #DIV/0! | T13: =(100*(F13+0.44*J13+Q13)*($C$15/3))/(C13*($F$15+0.44*$J$15+$Q$15)) -> #DIV/0! | U13: =S13/T13 -> #DIV/0! | V13: =100*Q13/(F13+0.44*J13+Q13) -> #DIV/0! | W13: =IF(V13=0,0,S13/V13) -> #DIV/0!
A15: SOMME | B15: =SUM(B2:B13) -> 56 | C15: =SUM(C2:C13) -> 738 | D15: =SUM(D2:D13) -> 657 | E15: =SUM(E2:E13) -> 267 | F15: =SUM(F2:F13) -> 591 | G15: =SUM(G2:G13) -> 47 | H15: =SUM(H2:H13) -> 167 | I15: =SUM(I2:I13) -> 42 | ... R15: =SUM(R2:R13) -> 138

Sheet LUNAR OWLS
A1: PLAYER | B1: GP | C1: MIN | D1: PTS | E1: FGM | F1: FGA | G1: 3PM | H1: 3PA | I1: FTM | J1: FTA | K1: OR | L1: DR | M1: REB | N1: AST | O1: STL | P1: BLK | Q1: TO | R1: PF | S1: AST% | T1: USG% | U1: R. PLAY | V1: TOV% | W1: AST% : TOV%
A2: Marina Mabrey | B2: 9 | C2: 189 | D2: 241 | E2: 88 | F2: 203 | G2: 34 | H2: 104 | I2: 19 | J2: 22 | K2: 7 | L2: 59 | M2: 66 | N2: 43 | O2: 4 | P2: 2 | Q2: 31 | R2: 28 | S2: =100*(N2)/((C2/($C$15/3))*$E$15-E2) -> 37.442665 | T2: =(100*(F2+0.44*J2+Q2)*($C$15/3))/(C2*($F$15+0.44*$J$15+$Q$15)) -> 43.952698 | U2: =S2/T2 -> 0.85188546 | V2: =100*Q2/(F2+0.44*J2+Q2) -> 12.721602 | W2: =IF(V2=0,0,S2/V2) -> 2.943235
A3: Aaliyah Edwards | B3: 8 | C3: 155 | D3: 178 | E3: 74 | F3: 128 | G3: 1 | H3: 2 | I3: 17 | J3: 24 | K3: 35 | L3: 74 | M3: 109 | N3: 15 | O3: 7 | P3: 4 | Q3: 30 | R3: 29 | S3: =100*(N3)/((C3/($C$15/3))*$E$15-E3) -> 16.242184 | T3: =(100*(F3+0.44*J3+Q3)*($C$15/3))/(C3*($F$15+0.44*$J$15+$Q$15)) -> 37.072364 | U3: =S3/T3 -> 0.43812107 | V3: =100*Q3/(F3+0.44*J3+Q3) -> 17.797817 | W3: =IF(V3=0,0,S3/V3) -> 0.91259417
A4: Skylar Diggins | B4: 7 | C4: 113 | D4: 108 | E4: 38 | F4: 106 | G4: 6 | H4: 34 | I4: 15 | J4: 18 | K4: 9 | L4: 15 | M4: 24 | N4: 25 | O4: 6 | P4: 8 | Q4: 12 | R4: 24 | S4: =100*(N4)/((C4/($C$15/3))*$E$15-E4) -> 30.020634 | T4: =(100*(F4+0.44*J4+Q4)*($C$15/3))/(C4*($F$15+0.44*$J$15+$Q$15)) -> 37.987764 | U4: =S4/T4 -> 0.79027115 | V4: =100*Q4/(F4+0.44*J4+Q4) -> 9.5298602 | W4: =IF(V4=0,0,S4/V4) -> 3.1501652
A5: Temi Fágbénlé | B5: 10 | C5: 87 | D5: 54 | E5: 25 | F5: 47 | G5: 2 | H5: 7 | I5: 1 | J5: 5 | K5: 12 | L5: 35 | M5: 47 | N5: 6 | O5: 6 | P5: 4 | Q5: 10 | R5: 21 | S5: =100*(N5)/((C5/($C$15/3))*$E$15-E5) -> 8.7755438 | T5: =(100*(F5+0.44*J5+Q5)*($C$15/3))/(C5*($F$15+0.44*$J$15+$Q$15)) -> 23.196898 | U5: =S5/T5 -> 0.37830678 | V5: =100*Q5/(F5+0.44*J5+Q5) -> 16.891892 | W5: =IF(V5=0,0,S5/V5) -> 0.5195122
A6: Rachel Banham | B6: 10 | C6: 60 | D6: 41 | E6: 14 | F6: 35 | G6: 13 | H6: 32 | I6: 0 | J6: 1 | K6: 1 | L6: 14 | M6: 15 | N6: 6 | O6: 1 | P6: 0 | Q6: 5 | R6: 23 | S6: =100*(N6)/((C6/($C$15/3))*$E$15-E6) -> 11.906093 | T6: =(100*(F6+0.44*J6+Q6)*($C$15/3))/(C6*($F$15+0.44*$J$15+$Q$15)) -> 22.976684 | U6: =S6/T6 -> 0.5181815 | V6: =100*Q6/(F6+0.44*J6+Q6) -> 12.363996 | W6: =IF(V6=0,0,S6/V6) -> 0.96296478
A7: Rebecca Allen | B7: 9 | C7: 106 | D7: 37 | E7: 15 | F7: 43 | G7: 7 | H7: 20 | I7: 0 | J7: 1 | K7: 6 | L7: 25 | M7: 31 | N7: 12 | O7: 3 | P7: 8 | Q7: 13 | R7: 34 | S7: =100*(N7)/((C7/($C$15/3))*$E$15-E7) -> 12.150252 | T7: =(100*(F7+0.44*J7+Q7)*($C$15/3))/(C7*($F$15+0.44*$J$15+$Q$15)) -> 18.151336 | U7: =S7/T7 -> 0.66938611 | V7: =100*Q7/(F7+0.44*J7+Q7) -> 23.03331 | W7: =IF(V7=0,0,S7/V7) -> 0.52750788
S8: =100*(N8)/((C8/($C$15/3))*$E$15-E8) -> #DIV/0! | T8: =(100*(F8+0.44*J8+Q8)*($C$15/3))/(C8*($F$15+0.44*$J$15+$Q$15)) -> #DIV/0! | U8: =S8/T8 -> #DIV/0! | V8: =100*Q8/(F8+0.44*J8+Q8) -> #DIV/0! | W8: =IF(V8=0,0,S8/V8) -> #DIV/0!
S9: =100*(N9)/((C9/($C$15/3))*$E$15-E9) -> #DIV/0! | T9: =(100*(F9+0.44*J9+Q9)*($C$15/3))/(C9*($F$15+0.44*$J$15+$Q$15)) -> #DIV/0! | U9: =S9/T9 -> #DIV/0! | V9: =100*Q9/(F9+0.44*J9+Q9) -> #DIV/0! | W9: =IF(V9=0,0,S9/V9) -> #DIV/0!
S10: =100*(N10)/((C10/($C$15/3))*$E$15-E10) -> #DIV/0! | T10: =(100*(F10+0.44*J10+Q10)*($C$15/3))/(C10*($F$15+0.44*$J$15+$Q$15)) -> #DIV/0! | U10: =S10/T10 -> #DIV/0! | V10: =100*Q10/(F10+0.44*J10+Q10) -> #DIV/0! | W10: =IF(V10=0,0,S10/V10) -> #DIV/0!
S11: =100*(N11)/((C11/($C$15/3))*$E$15-E11) -> #DIV/0! | T11: =(100*(F11+0.44*J11+Q11)*($C$15/3))/(C11*($F$15+0.44*$J$15+$Q$15)) -> #DIV/0! | U11: =S11/T11 -> #DIV/0! | V11: =100*Q11/(F11+0.44*J11+Q11) -> #DIV/0! | W11: =IF(V11=0,0,S11/V11) -> #DIV/0!
S12: =100*(N12)/((C12/($C$15/3))*$E$15-E12) -> #DIV/0! | T12: =(100*(F12+0.44*J12+Q12)*($C$15/3))/(C12*($F$15+0.44*$J$15+$Q$15)) -> #DIV/0! | U12: =S12/T12 -> #DIV/0! | V12: =100*Q12/(F12+0.44*J12+Q12) -> #DIV/0! | W12: =IF(V12=0,0,S12/V12) -> #DIV/0!
S13: =100*(N13)/((C13/($C$15/3))*$E$15-E13) -> #DIV/0! | T13: =(100*(F13+0.44*J13+Q13)*($C$15/3))/(C13*($F$15+0.44*$J$15+$Q$15)) -> #DIV/0! | U13: =S13/T13 -> #DIV/0! | V13: =100*Q13/(F13+0.44*J13+Q13) -> #DIV/0! | W13: =IF(V13=0,0,S13/V13) -> #DIV/0!
A15: SOMME | B15: =SUM(B2:B13) -> 53 | C15: =SUM(C2:C13) -> 710 | D15: =SUM(D2:D13) -> 659 | E15: =SUM(E2:E13) -> 254 | F15: =SUM(F2:F13) -> 562 | G15: =SUM(G2:G13) -> 63 | H15: =SUM(H2:H13) -> 199 | I15: =SUM(I2:I13) -> 52 | ... R15: =SUM(R2:R13) -> 159

Sheet PHANTOM
